2018-11-22 00:36:53,085 - INFO----  当前运行文件：F:/pythonProject/AutoDot\common\DataReplace.py
2018-11-22 00:36:53,085 - INFO----  当前运行文件：F:/pythonProject/AutoDot\common\SaveDynamicData.py
2018-11-22 00:36:53,085 - INFO----  当前运行文件：F:/pythonProject/AutoDot\common\ConfigFile.py
2018-11-22 00:36:53,217 - INFO----  ------------------------------------------------------------------
2018-11-22 00:36:53,217 - INFO----  当前运行文件：F:/pythonProject/AutoDot\common\HttpRequest.py
2018-11-22 00:36:54,857 - INFO----  Expand macros in F:\python3.6.5\lib\site-packages\macropy\core\hquotes.py
2018-11-22 00:36:54,857 - INFO----  Finding macros in 'macropy.core.hquotes'
2018-11-22 00:36:54,857 - INFO----  Importing macros from 'macropy.core.quotes' into 'macropy.core.hquotes'
2018-11-22 00:36:54,857 - INFO----  Expand macros in F:\python3.6.5\lib\site-packages\macropy\core\quotes.py
2018-11-22 00:36:54,857 - INFO----  Finding macros in 'macropy.core.quotes'
2018-11-22 00:36:54,889 - DEBUG----  Found macro 'q', type 'Block', line 48
2018-11-22 00:36:54,889 - DEBUG----  Found macro 'q', type 'Block', line 58
2018-11-22 00:36:54,920 - INFO----  Expand macros in F:\python3.6.5\lib\site-packages\macropy\core\failure.py
2018-11-22 00:36:54,920 - INFO----  Finding macros in 'macropy.core.failure'
2018-11-22 00:36:54,920 - INFO----  Importing macros from 'macropy.core.hquotes' into 'macropy.core.failure'
2018-11-22 00:36:54,941 - DEBUG----  Found macro 'hq', type 'Expr', line 29
2018-11-22 00:36:54,958 - DEBUG----  declare 'pyecharts_js_extension' plugin manager
2018-11-22 00:36:54,958 - DEBUG----  scanning for plugins...
2018-11-22 00:36:55,073 - DEBUG----  register Pypkg
2018-11-22 00:36:55,073 - DEBUG----  found jupyter_echarts_pypkg
2018-11-22 00:36:55,073 - DEBUG----  Loader for pyecharts_snapshot was unable to find the sources
2018-11-22 00:36:55,073 - ERROR----  failed to import pyecharts_snapshot
Traceback (most recent call last):
  File "F:\python3.6.5\lib\site-packages\lml\utils.py", line 43, in do_import
    plugin_module = __import__(plugin_module_name)
ModuleNotFoundError: No module named 'pyecharts_snapshot'
2018-11-22 00:36:55,073 - DEBUG----  pyecharts_snapshot
2018-11-22 00:36:55,073 - DEBUG----  No module named 'pyecharts_snapshot'
2018-11-22 00:36:55,073 - DEBUG----  scanning done
2018-11-22 00:36:55,073 - DEBUG----  caching EchartsEnvironment
2018-11-22 00:36:55,089 - DEBUG----  declare 'pyecharts_environment' plugin manager
2018-11-22 00:36:55,089 - DEBUG----  load cached plugin info: EchartsEnvironment
2018-11-22 00:36:55,089 - DEBUG----  load None later
2018-11-22 00:36:55,104 - DEBUG----  caching DefaultChinaDataBank
2018-11-22 00:36:55,104 - DEBUG----  declare 'pyecharts_geo_data_bank' plugin manager
2018-11-22 00:36:55,104 - DEBUG----  load cached plugin info: DefaultChinaDataBank
2018-11-22 00:36:55,104 - DEBUG----  load None later
2018-11-22 00:36:55,174 - DEBUG----  Loader for django.contrib.auth.templatetags was unable to find the sources
2018-11-22 00:36:55,174 - DEBUG----  Loader for django.contrib.contenttypes.templatetags was unable to find the sources
2018-11-22 00:36:55,174 - DEBUG----  Loader for django.contrib.sessions.templatetags was unable to find the sources
2018-11-22 00:36:55,174 - DEBUG----  Loader for django.contrib.messages.templatetags was unable to find the sources
2018-11-22 00:36:55,189 - DEBUG----  Loader for DotDotDot.templatetags was unable to find the sources
2018-11-22 00:36:55,221 - DEBUG----  Loader for django.contrib.messages.migrations was unable to find the sources
2018-11-22 00:36:55,221 - DEBUG----  Loader for django.contrib.staticfiles.migrations was unable to find the sources
2018-11-22 00:37:28,549 - INFO----  ------------------------------------------------------------------
2018-11-22 00:37:28,549 - INFO----  当前运行文件：F:/pythonProject/AutoDot\common\GetProjectName.py
2018-11-22 00:37:28,550 - INFO----  F:\pythonProject\AutoDot\case文件下的用例文件 ['自动干线.xlsx']
2018-11-22 00:37:28,631 - INFO----  ------------------------------------------------------------------
2018-11-22 00:37:28,632 - INFO----  当前运行文件：F:/pythonProject/AutoDot\common\GetProjectName.py
2018-11-22 00:37:28,632 - INFO----  F:\pythonProject\AutoDot\case文件下的用例文件 ['自动干线.xlsx']
2018-11-22 00:37:28,687 - WARNING----  Not Found: /favicon.ico
2018-11-22 00:37:28,691 - WARNING----  Not Found: /favicon.ico
2018-11-22 00:37:31,430 - INFO----  ------------------------------------------------------------------
2018-11-22 00:37:31,430 - INFO----  当前运行文件：F:/pythonProject/AutoDot\common\GetProjectCase.py
2018-11-22 00:37:31,430 - INFO----  准备获取 自动干线 项目的用例路径
2018-11-22 00:37:31,431 - INFO----  获取到 自动干线 项目的用例路径：F:\pythonProject\AutoDot\case\自动干线.xlsx
2018-11-22 00:37:31,437 - INFO----  获取用例的标题：['ID', 'Run', 'Sort', 'Sql', 'ModuleName', 'CaseName', 'CaseDescription', 'Protocol', 'Host', 'Method', 'Headers', 'Path', 'Data', 'Files', 'ReplaceID', 'Expect', 'CheckPoint', 'Response', 'TransmitID', 'TransmitTargetID', 'Remark', 'CreateDate', 'UpdateTime', 'Author', 'Editor', 'RunResult']
2018-11-22 00:37:31,437 - INFO----  获取 “自动干线” 所有用例：[{'ID': 1.0, 'Run': 'YES', 'Sort': 1.0, 'Sql': '', 'ModuleName': '百度测试', 'CaseName': '百度', 'CaseDescription': '测试', 'Protocol': 'http://', 'Host': 'www.baidu.com', 'Method': 'GET', 'Headers': 'application/x-www-form-urlencoded', 'Path': '', 'Data': '', 'Files': '', 'ReplaceID': '', 'Expect': "<!DOCTYPE html>\n<!--STATUS OK--><html> <head><meta http-equiv=content-type content=text/html;charset=utf-8><meta http-equiv=X-UA-Compatible content=IE=Edge><meta content=always name=referrer><link rel=stylesheet type=text/css href=http://s1.bdstatic.com/r/www/cache/bdorz/baidu.min.css><title>百度一下，你就知道</title></head> <body link=#0000cc> <div id=wrapper> <div id=head> <div class=head_wrapper> <div class=s_form> <div class=s_form_wrapper> <div id=lg> <img hidefocus=true src=//www.baidu.com/img/bd_logo1.png width=270 height=129> </div> <form id=form name=f action=//www.baidu.com/s class=fm> <input type=hidden name=bdorz_come value=1> <input type=hidden name=ie value=utf-8> <input type=hidden name=f value=8> <input type=hidden name=rsv_bp value=1> <input type=hidden name=rsv_idx value=1> <input type=hidden name=tn value=baidu><span class='bg s_ipt_wr'><input id=kw name=wd class=s_ipt value maxlength=255 autocomplete=off autofocus></span><span class='bg s_btn_wr'><input type=submit id=su value=百度一下 class='bg s_btn'></span> </form> </div> </div> <div id=u1> <a href=http://news.baidu.com name=tj_trnews class=mnav>新闻</a> <a href=http://www.hao123.com name=tj_trhao123 class=mnav>hao123</a> <a href=http://map.baidu.com name=tj_trmap class=mnav>地图</a> <a href=http://v.baidu.com name=tj_trvideo class=mnav>视频</a> <a href=http://tieba.baidu.com name=tj_trtieba class=mnav>贴吧</a> <noscript> <a href=http://www.baidu.com/bdorz/login.gif?login&amp;tpl=mn&amp;u=http%3A%2F%2Fwww.baidu.com%2f%3fbdorz_come%3d1 name=tj_login class=lb>登录</a> </noscript> <script>document.write('<a href='http://www.baidu.com/bdorz/login.gif?login&tpl=mn&u='+ encodeURIComponent(window.location.href+ (window.location.search === '' ? '?' : '&')+ 'bdorz_come=1')+ '' name='tj_login' class='lb'>登录</a>');</script> <a href=//www.baidu.com/more/ name=tj_briicon class=bri style='display: block;'>更多产品</a> </div> </div> </div> <div id=ftCon> <div id=ftConw> <p id=lh> <a href=http://home.baidu.com>关于百度</a> <a href=http://ir.baidu.com>About Baidu</a> </p> <p id=cp>&copy;2017&nbsp;Baidu&nbsp;<a href=http://www.baidu.com/duty/>使用百度前必读</a>&nbsp; <a href=http://jianyi.baidu.com/ class=cp-feedback>意见反馈</a>&nbsp;京ICP证030173号&nbsp; <img src=//www.baidu.com/img/gs.gif> </p> </div> </div> </div> </body> </html>", 'CheckPoint': '', 'Response': '', 'TransmitID': '', 'TransmitTargetID': '', 'Remark': '', 'CreateDate': '20181121212402', 'UpdateTime': '20181121220333', 'Author': 'GRUNMI', 'Editor': 'GRUNMI', 'RunResult': '', 'RowID': 2}]
2018-11-22 00:37:35,389 - ERROR----  Internal Server Error: /add/case/
Traceback (most recent call last):
  File "F:\python3.6.5\lib\site-packages\django\db\backends\utils.py", line 85, in _execute
    return self.cursor.execute(sql, params)
  File "F:\python3.6.5\lib\site-packages\django\db\backends\sqlite3\base.py", line 303, in execute
    return Database.Cursor.execute(self, query, params)
sqlite3.OperationalError: no such table: django_session

The above exception was the direct cause of the following exception:

Traceback (most recent call last):
  File "F:\python3.6.5\lib\site-packages\django\core\handlers\exception.py", line 35, in inner
    response = get_response(request)
  File "F:\python3.6.5\lib\site-packages\django\utils\deprecation.py", line 97, in __call__
    response = self.process_response(request, response)
  File "F:\python3.6.5\lib\site-packages\django\contrib\sessions\middleware.py", line 58, in process_response
    request.session.save()
  File "F:\python3.6.5\lib\site-packages\django\contrib\sessions\backends\db.py", line 79, in save
    return self.create()
  File "F:\python3.6.5\lib\site-packages\django\contrib\sessions\backends\db.py", line 49, in create
    self._session_key = self._get_new_session_key()
  File "F:\python3.6.5\lib\site-packages\django\contrib\sessions\backends\base.py", line 153, in _get_new_session_key
    if not self.exists(session_key):
  File "F:\python3.6.5\lib\site-packages\django\contrib\sessions\backends\db.py", line 45, in exists
    return self.model.objects.filter(session_key=session_key).exists()
  File "F:\python3.6.5\lib\site-packages\django\db\models\query.py", line 715, in exists
    return self.query.has_results(using=self.db)
  File "F:\python3.6.5\lib\site-packages\django\db\models\sql\query.py", line 509, in has_results
    return compiler.has_results()
  File "F:\python3.6.5\lib\site-packages\django\db\models\sql\compiler.py", line 1037, in has_results
    return bool(self.execute_sql(SINGLE))
  File "F:\python3.6.5\lib\site-packages\django\db\models\sql\compiler.py", line 1068, in execute_sql
    cursor.execute(sql, params)
  File "F:\python3.6.5\lib\site-packages\django\db\backends\utils.py", line 100, in execute
    return super().execute(sql, params)
  File "F:\python3.6.5\lib\site-packages\django\db\backends\utils.py", line 68, in execute
    return self._execute_with_wrappers(sql, params, many=False, executor=self._execute)
  File "F:\python3.6.5\lib\site-packages\django\db\backends\utils.py", line 77, in _execute_with_wrappers
    return executor(sql, params, many, context)
  File "F:\python3.6.5\lib\site-packages\django\db\backends\utils.py", line 85, in _execute
    return self.cursor.execute(sql, params)
  File "F:\python3.6.5\lib\site-packages\django\db\utils.py", line 89, in __exit__
    raise dj_exc_value.with_traceback(traceback) from exc_value
  File "F:\python3.6.5\lib\site-packages\django\db\backends\utils.py", line 85, in _execute
    return self.cursor.execute(sql, params)
  File "F:\python3.6.5\lib\site-packages\django\db\backends\sqlite3\base.py", line 303, in execute
    return Database.Cursor.execute(self, query, params)
django.db.utils.OperationalError: no such table: django_session
2018-11-22 00:37:35,587 - DEBUG----  Loader for django.conf.locale.en_US was unable to find the sources
2018-11-22 00:37:36,694 - ERROR----  Internal Server Error: /add/case/
Traceback (most recent call last):
  File "F:\python3.6.5\lib\site-packages\django\db\backends\utils.py", line 85, in _execute
    return self.cursor.execute(sql, params)
  File "F:\python3.6.5\lib\site-packages\django\db\backends\sqlite3\base.py", line 303, in execute
    return Database.Cursor.execute(self, query, params)
sqlite3.OperationalError: no such table: django_session

The above exception was the direct cause of the following exception:

Traceback (most recent call last):
  File "F:\python3.6.5\lib\site-packages\django\core\handlers\exception.py", line 35, in inner
    response = get_response(request)
  File "F:\python3.6.5\lib\site-packages\django\utils\deprecation.py", line 97, in __call__
    response = self.process_response(request, response)
  File "F:\python3.6.5\lib\site-packages\django\contrib\sessions\middleware.py", line 58, in process_response
    request.session.save()
  File "F:\python3.6.5\lib\site-packages\django\contrib\sessions\backends\db.py", line 79, in save
    return self.create()
  File "F:\python3.6.5\lib\site-packages\django\contrib\sessions\backends\db.py", line 49, in create
    self._session_key = self._get_new_session_key()
  File "F:\python3.6.5\lib\site-packages\django\contrib\sessions\backends\base.py", line 153, in _get_new_session_key
    if not self.exists(session_key):
  File "F:\python3.6.5\lib\site-packages\django\contrib\sessions\backends\db.py", line 45, in exists
    return self.model.objects.filter(session_key=session_key).exists()
  File "F:\python3.6.5\lib\site-packages\django\db\models\query.py", line 715, in exists
    return self.query.has_results(using=self.db)
  File "F:\python3.6.5\lib\site-packages\django\db\models\sql\query.py", line 509, in has_results
    return compiler.has_results()
  File "F:\python3.6.5\lib\site-packages\django\db\models\sql\compiler.py", line 1037, in has_results
    return bool(self.execute_sql(SINGLE))
  File "F:\python3.6.5\lib\site-packages\django\db\models\sql\compiler.py", line 1068, in execute_sql
    cursor.execute(sql, params)
  File "F:\python3.6.5\lib\site-packages\django\db\backends\utils.py", line 100, in execute
    return super().execute(sql, params)
  File "F:\python3.6.5\lib\site-packages\django\db\backends\utils.py", line 68, in execute
    return self._execute_with_wrappers(sql, params, many=False, executor=self._execute)
  File "F:\python3.6.5\lib\site-packages\django\db\backends\utils.py", line 77, in _execute_with_wrappers
    return executor(sql, params, many, context)
  File "F:\python3.6.5\lib\site-packages\django\db\backends\utils.py", line 85, in _execute
    return self.cursor.execute(sql, params)
  File "F:\python3.6.5\lib\site-packages\django\db\utils.py", line 89, in __exit__
    raise dj_exc_value.with_traceback(traceback) from exc_value
  File "F:\python3.6.5\lib\site-packages\django\db\backends\utils.py", line 85, in _execute
    return self.cursor.execute(sql, params)
  File "F:\python3.6.5\lib\site-packages\django\db\backends\sqlite3\base.py", line 303, in execute
    return Database.Cursor.execute(self, query, params)
django.db.utils.OperationalError: no such table: django_session
2018-11-22 00:37:37,360 - ERROR----  Internal Server Error: /add/case/
Traceback (most recent call last):
  File "F:\python3.6.5\lib\site-packages\django\db\backends\utils.py", line 85, in _execute
    return self.cursor.execute(sql, params)
  File "F:\python3.6.5\lib\site-packages\django\db\backends\sqlite3\base.py", line 303, in execute
    return Database.Cursor.execute(self, query, params)
sqlite3.OperationalError: no such table: django_session

The above exception was the direct cause of the following exception:

Traceback (most recent call last):
  File "F:\python3.6.5\lib\site-packages\django\core\handlers\exception.py", line 35, in inner
    response = get_response(request)
  File "F:\python3.6.5\lib\site-packages\django\utils\deprecation.py", line 97, in __call__
    response = self.process_response(request, response)
  File "F:\python3.6.5\lib\site-packages\django\contrib\sessions\middleware.py", line 58, in process_response
    request.session.save()
  File "F:\python3.6.5\lib\site-packages\django\contrib\sessions\backends\db.py", line 79, in save
    return self.create()
  File "F:\python3.6.5\lib\site-packages\django\contrib\sessions\backends\db.py", line 49, in create
    self._session_key = self._get_new_session_key()
  File "F:\python3.6.5\lib\site-packages\django\contrib\sessions\backends\base.py", line 153, in _get_new_session_key
    if not self.exists(session_key):
  File "F:\python3.6.5\lib\site-packages\django\contrib\sessions\backends\db.py", line 45, in exists
    return self.model.objects.filter(session_key=session_key).exists()
  File "F:\python3.6.5\lib\site-packages\django\db\models\query.py", line 715, in exists
    return self.query.has_results(using=self.db)
  File "F:\python3.6.5\lib\site-packages\django\db\models\sql\query.py", line 509, in has_results
    return compiler.has_results()
  File "F:\python3.6.5\lib\site-packages\django\db\models\sql\compiler.py", line 1037, in has_results
    return bool(self.execute_sql(SINGLE))
  File "F:\python3.6.5\lib\site-packages\django\db\models\sql\compiler.py", line 1068, in execute_sql
    cursor.execute(sql, params)
  File "F:\python3.6.5\lib\site-packages\django\db\backends\utils.py", line 100, in execute
    return super().execute(sql, params)
  File "F:\python3.6.5\lib\site-packages\django\db\backends\utils.py", line 68, in execute
    return self._execute_with_wrappers(sql, params, many=False, executor=self._execute)
  File "F:\python3.6.5\lib\site-packages\django\db\backends\utils.py", line 77, in _execute_with_wrappers
    return executor(sql, params, many, context)
  File "F:\python3.6.5\lib\site-packages\django\db\backends\utils.py", line 85, in _execute
    return self.cursor.execute(sql, params)
  File "F:\python3.6.5\lib\site-packages\django\db\utils.py", line 89, in __exit__
    raise dj_exc_value.with_traceback(traceback) from exc_value
  File "F:\python3.6.5\lib\site-packages\django\db\backends\utils.py", line 85, in _execute
    return self.cursor.execute(sql, params)
  File "F:\python3.6.5\lib\site-packages\django\db\backends\sqlite3\base.py", line 303, in execute
    return Database.Cursor.execute(self, query, params)
django.db.utils.OperationalError: no such table: django_session
2018-11-22 00:37:39,047 - INFO----  ------------------------------------------------------------------
2018-11-22 00:37:39,048 - INFO----  当前运行文件：F:/pythonProject/AutoDot\common\GetProjectCase.py
2018-11-22 00:37:39,048 - INFO----  准备获取 自动干线 项目的用例路径
2018-11-22 00:37:39,049 - INFO----  获取到 自动干线 项目的用例路径：F:\pythonProject\AutoDot\case\自动干线.xlsx
2018-11-22 00:37:39,055 - INFO----  获取用例的标题：['ID', 'Run', 'Sort', 'Sql', 'ModuleName', 'CaseName', 'CaseDescription', 'Protocol', 'Host', 'Method', 'Headers', 'Path', 'Data', 'Files', 'ReplaceID', 'Expect', 'CheckPoint', 'Response', 'TransmitID', 'TransmitTargetID', 'Remark', 'CreateDate', 'UpdateTime', 'Author', 'Editor', 'RunResult']
2018-11-22 00:37:39,055 - INFO----  获取 “自动干线” 所有用例：[{'ID': 1.0, 'Run': 'YES', 'Sort': 1.0, 'Sql': '', 'ModuleName': '百度测试', 'CaseName': '百度', 'CaseDescription': '测试', 'Protocol': 'http://', 'Host': 'www.baidu.com', 'Method': 'GET', 'Headers': 'application/x-www-form-urlencoded', 'Path': '', 'Data': '', 'Files': '', 'ReplaceID': '', 'Expect': "<!DOCTYPE html>\n<!--STATUS OK--><html> <head><meta http-equiv=content-type content=text/html;charset=utf-8><meta http-equiv=X-UA-Compatible content=IE=Edge><meta content=always name=referrer><link rel=stylesheet type=text/css href=http://s1.bdstatic.com/r/www/cache/bdorz/baidu.min.css><title>百度一下，你就知道</title></head> <body link=#0000cc> <div id=wrapper> <div id=head> <div class=head_wrapper> <div class=s_form> <div class=s_form_wrapper> <div id=lg> <img hidefocus=true src=//www.baidu.com/img/bd_logo1.png width=270 height=129> </div> <form id=form name=f action=//www.baidu.com/s class=fm> <input type=hidden name=bdorz_come value=1> <input type=hidden name=ie value=utf-8> <input type=hidden name=f value=8> <input type=hidden name=rsv_bp value=1> <input type=hidden name=rsv_idx value=1> <input type=hidden name=tn value=baidu><span class='bg s_ipt_wr'><input id=kw name=wd class=s_ipt value maxlength=255 autocomplete=off autofocus></span><span class='bg s_btn_wr'><input type=submit id=su value=百度一下 class='bg s_btn'></span> </form> </div> </div> <div id=u1> <a href=http://news.baidu.com name=tj_trnews class=mnav>新闻</a> <a href=http://www.hao123.com name=tj_trhao123 class=mnav>hao123</a> <a href=http://map.baidu.com name=tj_trmap class=mnav>地图</a> <a href=http://v.baidu.com name=tj_trvideo class=mnav>视频</a> <a href=http://tieba.baidu.com name=tj_trtieba class=mnav>贴吧</a> <noscript> <a href=http://www.baidu.com/bdorz/login.gif?login&amp;tpl=mn&amp;u=http%3A%2F%2Fwww.baidu.com%2f%3fbdorz_come%3d1 name=tj_login class=lb>登录</a> </noscript> <script>document.write('<a href='http://www.baidu.com/bdorz/login.gif?login&tpl=mn&u='+ encodeURIComponent(window.location.href+ (window.location.search === '' ? '?' : '&')+ 'bdorz_come=1')+ '' name='tj_login' class='lb'>登录</a>');</script> <a href=//www.baidu.com/more/ name=tj_briicon class=bri style='display: block;'>更多产品</a> </div> </div> </div> <div id=ftCon> <div id=ftConw> <p id=lh> <a href=http://home.baidu.com>关于百度</a> <a href=http://ir.baidu.com>About Baidu</a> </p> <p id=cp>&copy;2017&nbsp;Baidu&nbsp;<a href=http://www.baidu.com/duty/>使用百度前必读</a>&nbsp; <a href=http://jianyi.baidu.com/ class=cp-feedback>意见反馈</a>&nbsp;京ICP证030173号&nbsp; <img src=//www.baidu.com/img/gs.gif> </p> </div> </div> </div> </body> </html>", 'CheckPoint': '', 'Response': '', 'TransmitID': '', 'TransmitTargetID': '', 'Remark': '', 'CreateDate': '20181121212402', 'UpdateTime': '20181121220333', 'Author': 'GRUNMI', 'Editor': 'GRUNMI', 'RunResult': '', 'RowID': 2}]
2018-11-22 00:37:41,060 - INFO----  ------------------------------------------------------------------
2018-11-22 00:37:41,060 - INFO----  当前运行文件：F:/pythonProject/AutoDot\common\GetProjectCase.py
2018-11-22 00:37:41,060 - INFO----  准备获取 自动干线 项目的用例路径
2018-11-22 00:37:41,061 - INFO----  获取到 自动干线 项目的用例路径：F:\pythonProject\AutoDot\case\自动干线.xlsx
2018-11-22 00:37:41,066 - INFO----  获取用例的标题：['ID', 'Run', 'Sort', 'Sql', 'ModuleName', 'CaseName', 'CaseDescription', 'Protocol', 'Host', 'Method', 'Headers', 'Path', 'Data', 'Files', 'ReplaceID', 'Expect', 'CheckPoint', 'Response', 'TransmitID', 'TransmitTargetID', 'Remark', 'CreateDate', 'UpdateTime', 'Author', 'Editor', 'RunResult']
2018-11-22 00:37:41,066 - INFO----  获取 “自动干线” 所有用例：[{'ID': 1.0, 'Run': 'YES', 'Sort': 1.0, 'Sql': '', 'ModuleName': '百度测试', 'CaseName': '百度', 'CaseDescription': '测试', 'Protocol': 'http://', 'Host': 'www.baidu.com', 'Method': 'GET', 'Headers': 'application/x-www-form-urlencoded', 'Path': '', 'Data': '', 'Files': '', 'ReplaceID': '', 'Expect': "<!DOCTYPE html>\n<!--STATUS OK--><html> <head><meta http-equiv=content-type content=text/html;charset=utf-8><meta http-equiv=X-UA-Compatible content=IE=Edge><meta content=always name=referrer><link rel=stylesheet type=text/css href=http://s1.bdstatic.com/r/www/cache/bdorz/baidu.min.css><title>百度一下，你就知道</title></head> <body link=#0000cc> <div id=wrapper> <div id=head> <div class=head_wrapper> <div class=s_form> <div class=s_form_wrapper> <div id=lg> <img hidefocus=true src=//www.baidu.com/img/bd_logo1.png width=270 height=129> </div> <form id=form name=f action=//www.baidu.com/s class=fm> <input type=hidden name=bdorz_come value=1> <input type=hidden name=ie value=utf-8> <input type=hidden name=f value=8> <input type=hidden name=rsv_bp value=1> <input type=hidden name=rsv_idx value=1> <input type=hidden name=tn value=baidu><span class='bg s_ipt_wr'><input id=kw name=wd class=s_ipt value maxlength=255 autocomplete=off autofocus></span><span class='bg s_btn_wr'><input type=submit id=su value=百度一下 class='bg s_btn'></span> </form> </div> </div> <div id=u1> <a href=http://news.baidu.com name=tj_trnews class=mnav>新闻</a> <a href=http://www.hao123.com name=tj_trhao123 class=mnav>hao123</a> <a href=http://map.baidu.com name=tj_trmap class=mnav>地图</a> <a href=http://v.baidu.com name=tj_trvideo class=mnav>视频</a> <a href=http://tieba.baidu.com name=tj_trtieba class=mnav>贴吧</a> <noscript> <a href=http://www.baidu.com/bdorz/login.gif?login&amp;tpl=mn&amp;u=http%3A%2F%2Fwww.baidu.com%2f%3fbdorz_come%3d1 name=tj_login class=lb>登录</a> </noscript> <script>document.write('<a href='http://www.baidu.com/bdorz/login.gif?login&tpl=mn&u='+ encodeURIComponent(window.location.href+ (window.location.search === '' ? '?' : '&')+ 'bdorz_come=1')+ '' name='tj_login' class='lb'>登录</a>');</script> <a href=//www.baidu.com/more/ name=tj_briicon class=bri style='display: block;'>更多产品</a> </div> </div> </div> <div id=ftCon> <div id=ftConw> <p id=lh> <a href=http://home.baidu.com>关于百度</a> <a href=http://ir.baidu.com>About Baidu</a> </p> <p id=cp>&copy;2017&nbsp;Baidu&nbsp;<a href=http://www.baidu.com/duty/>使用百度前必读</a>&nbsp; <a href=http://jianyi.baidu.com/ class=cp-feedback>意见反馈</a>&nbsp;京ICP证030173号&nbsp; <img src=//www.baidu.com/img/gs.gif> </p> </div> </div> </div> </body> </html>", 'CheckPoint': '', 'Response': '', 'TransmitID': '', 'TransmitTargetID': '', 'Remark': '', 'CreateDate': '20181121212402', 'UpdateTime': '20181121220333', 'Author': 'GRUNMI', 'Editor': 'GRUNMI', 'RunResult': '', 'RowID': 2}]
2018-11-22 00:37:42,233 - ERROR----  Internal Server Error: /editor/case/
Traceback (most recent call last):
  File "F:\python3.6.5\lib\site-packages\django\db\backends\utils.py", line 85, in _execute
    return self.cursor.execute(sql, params)
  File "F:\python3.6.5\lib\site-packages\django\db\backends\sqlite3\base.py", line 303, in execute
    return Database.Cursor.execute(self, query, params)
sqlite3.OperationalError: no such table: django_session

The above exception was the direct cause of the following exception:

Traceback (most recent call last):
  File "F:\python3.6.5\lib\site-packages\django\core\handlers\exception.py", line 35, in inner
    response = get_response(request)
  File "F:\python3.6.5\lib\site-packages\django\utils\deprecation.py", line 97, in __call__
    response = self.process_response(request, response)
  File "F:\python3.6.5\lib\site-packages\django\contrib\sessions\middleware.py", line 58, in process_response
    request.session.save()
  File "F:\python3.6.5\lib\site-packages\django\contrib\sessions\backends\db.py", line 79, in save
    return self.create()
  File "F:\python3.6.5\lib\site-packages\django\contrib\sessions\backends\db.py", line 49, in create
    self._session_key = self._get_new_session_key()
  File "F:\python3.6.5\lib\site-packages\django\contrib\sessions\backends\base.py", line 153, in _get_new_session_key
    if not self.exists(session_key):
  File "F:\python3.6.5\lib\site-packages\django\contrib\sessions\backends\db.py", line 45, in exists
    return self.model.objects.filter(session_key=session_key).exists()
  File "F:\python3.6.5\lib\site-packages\django\db\models\query.py", line 715, in exists
    return self.query.has_results(using=self.db)
  File "F:\python3.6.5\lib\site-packages\django\db\models\sql\query.py", line 509, in has_results
    return compiler.has_results()
  File "F:\python3.6.5\lib\site-packages\django\db\models\sql\compiler.py", line 1037, in has_results
    return bool(self.execute_sql(SINGLE))
  File "F:\python3.6.5\lib\site-packages\django\db\models\sql\compiler.py", line 1068, in execute_sql
    cursor.execute(sql, params)
  File "F:\python3.6.5\lib\site-packages\django\db\backends\utils.py", line 100, in execute
    return super().execute(sql, params)
  File "F:\python3.6.5\lib\site-packages\django\db\backends\utils.py", line 68, in execute
    return self._execute_with_wrappers(sql, params, many=False, executor=self._execute)
  File "F:\python3.6.5\lib\site-packages\django\db\backends\utils.py", line 77, in _execute_with_wrappers
    return executor(sql, params, many, context)
  File "F:\python3.6.5\lib\site-packages\django\db\backends\utils.py", line 85, in _execute
    return self.cursor.execute(sql, params)
  File "F:\python3.6.5\lib\site-packages\django\db\utils.py", line 89, in __exit__
    raise dj_exc_value.with_traceback(traceback) from exc_value
  File "F:\python3.6.5\lib\site-packages\django\db\backends\utils.py", line 85, in _execute
    return self.cursor.execute(sql, params)
  File "F:\python3.6.5\lib\site-packages\django\db\backends\sqlite3\base.py", line 303, in execute
    return Database.Cursor.execute(self, query, params)
django.db.utils.OperationalError: no such table: django_session
2018-11-22 00:37:43,592 - ERROR----  Internal Server Error: /editor/case/
Traceback (most recent call last):
  File "F:\python3.6.5\lib\site-packages\django\db\backends\utils.py", line 85, in _execute
    return self.cursor.execute(sql, params)
  File "F:\python3.6.5\lib\site-packages\django\db\backends\sqlite3\base.py", line 303, in execute
    return Database.Cursor.execute(self, query, params)
sqlite3.OperationalError: no such table: django_session

The above exception was the direct cause of the following exception:

Traceback (most recent call last):
  File "F:\python3.6.5\lib\site-packages\django\core\handlers\exception.py", line 35, in inner
    response = get_response(request)
  File "F:\python3.6.5\lib\site-packages\django\utils\deprecation.py", line 97, in __call__
    response = self.process_response(request, response)
  File "F:\python3.6.5\lib\site-packages\django\contrib\sessions\middleware.py", line 58, in process_response
    request.session.save()
  File "F:\python3.6.5\lib\site-packages\django\contrib\sessions\backends\db.py", line 79, in save
    return self.create()
  File "F:\python3.6.5\lib\site-packages\django\contrib\sessions\backends\db.py", line 49, in create
    self._session_key = self._get_new_session_key()
  File "F:\python3.6.5\lib\site-packages\django\contrib\sessions\backends\base.py", line 153, in _get_new_session_key
    if not self.exists(session_key):
  File "F:\python3.6.5\lib\site-packages\django\contrib\sessions\backends\db.py", line 45, in exists
    return self.model.objects.filter(session_key=session_key).exists()
  File "F:\python3.6.5\lib\site-packages\django\db\models\query.py", line 715, in exists
    return self.query.has_results(using=self.db)
  File "F:\python3.6.5\lib\site-packages\django\db\models\sql\query.py", line 509, in has_results
    return compiler.has_results()
  File "F:\python3.6.5\lib\site-packages\django\db\models\sql\compiler.py", line 1037, in has_results
    return bool(self.execute_sql(SINGLE))
  File "F:\python3.6.5\lib\site-packages\django\db\models\sql\compiler.py", line 1068, in execute_sql
    cursor.execute(sql, params)
  File "F:\python3.6.5\lib\site-packages\django\db\backends\utils.py", line 100, in execute
    return super().execute(sql, params)
  File "F:\python3.6.5\lib\site-packages\django\db\backends\utils.py", line 68, in execute
    return self._execute_with_wrappers(sql, params, many=False, executor=self._execute)
  File "F:\python3.6.5\lib\site-packages\django\db\backends\utils.py", line 77, in _execute_with_wrappers
    return executor(sql, params, many, context)
  File "F:\python3.6.5\lib\site-packages\django\db\backends\utils.py", line 85, in _execute
    return self.cursor.execute(sql, params)
  File "F:\python3.6.5\lib\site-packages\django\db\utils.py", line 89, in __exit__
    raise dj_exc_value.with_traceback(traceback) from exc_value
  File "F:\python3.6.5\lib\site-packages\django\db\backends\utils.py", line 85, in _execute
    return self.cursor.execute(sql, params)
  File "F:\python3.6.5\lib\site-packages\django\db\backends\sqlite3\base.py", line 303, in execute
    return Database.Cursor.execute(self, query, params)
django.db.utils.OperationalError: no such table: django_session
2018-11-22 00:37:44,206 - INFO----  当前运行文件：F:/pythonProject/AutoDot\common\CaseData.py
2018-11-22 00:37:44,206 - INFO----  调用运行create_project方法
2018-11-22 00:37:44,207 - INFO----  ------------------------------------------------------------------
2018-11-22 00:37:44,207 - INFO----  当前运行文件：F:/pythonProject/AutoDot\common\CreateProject.py
2018-11-22 00:37:44,208 - INFO----  已存在自动干线用例文件：F:\pythonProject\AutoDot\case\自动干线.xlsx
2018-11-22 00:37:44,208 - INFO----  打开F:\pythonProject\AutoDot\case\自动干线.xlsx文件
2018-11-22 00:37:44,233 - INFO----  已匹配到自动干线的用例表为：自动干线InterfaceData
2018-11-22 00:37:44,233 - INFO----  获取当前<Worksheet "自动干线InterfaceData">表的最大行数：2
2018-11-22 00:37:44,234 - INFO----  准备删除<Worksheet "自动干线InterfaceData">表中，id为1的用例数据
2018-11-22 00:37:44,234 - INFO----  删除<Worksheet "自动干线InterfaceData">表中，id为1的用例数据成功
2018-11-22 00:37:44,235 - INFO----  删除<Worksheet "自动干线InterfaceData">表中，第1条用例数据
2018-11-22 00:37:44,235 - INFO----  总共有1条用例数据
2018-11-22 00:37:44,235 - INFO----  准备保存<Worksheet "自动干线InterfaceData">表
2018-11-22 00:37:44,262 - INFO----  保存<Worksheet "自动干线InterfaceData">表成功，准备关闭自动干线工作簿
2018-11-22 00:37:44,262 - INFO----  关闭自动干线工作簿成功
2018-11-22 00:37:44,371 - INFO----  ------------------------------------------------------------------
2018-11-22 00:37:44,372 - INFO----  当前运行文件：F:/pythonProject/AutoDot\common\GetProjectCase.py
2018-11-22 00:37:44,372 - INFO----  准备获取 自动干线 项目的用例路径
2018-11-22 00:37:44,372 - INFO----  获取到 自动干线 项目的用例路径：F:\pythonProject\AutoDot\case\自动干线.xlsx
2018-11-22 00:37:44,377 - INFO----  获取用例的标题：['ID', 'Run', 'Sort', 'Sql', 'ModuleName', 'CaseName', 'CaseDescription', 'Protocol', 'Host', 'Method', 'Headers', 'Path', 'Data', 'Files', 'ReplaceID', 'Expect', 'CheckPoint', 'Response', 'TransmitID', 'TransmitTargetID', 'Remark', 'CreateDate', 'UpdateTime', 'Author', 'Editor', 'RunResult']
2018-11-22 00:37:46,903 - ERROR----  Internal Server Error: /add/case/
Traceback (most recent call last):
  File "F:\python3.6.5\lib\site-packages\django\db\backends\utils.py", line 85, in _execute
    return self.cursor.execute(sql, params)
  File "F:\python3.6.5\lib\site-packages\django\db\backends\sqlite3\base.py", line 303, in execute
    return Database.Cursor.execute(self, query, params)
sqlite3.OperationalError: no such table: django_session

The above exception was the direct cause of the following exception:

Traceback (most recent call last):
  File "F:\python3.6.5\lib\site-packages\django\core\handlers\exception.py", line 35, in inner
    response = get_response(request)
  File "F:\python3.6.5\lib\site-packages\django\utils\deprecation.py", line 97, in __call__
    response = self.process_response(request, response)
  File "F:\python3.6.5\lib\site-packages\django\contrib\sessions\middleware.py", line 58, in process_response
    request.session.save()
  File "F:\python3.6.5\lib\site-packages\django\contrib\sessions\backends\db.py", line 79, in save
    return self.create()
  File "F:\python3.6.5\lib\site-packages\django\contrib\sessions\backends\db.py", line 49, in create
    self._session_key = self._get_new_session_key()
  File "F:\python3.6.5\lib\site-packages\django\contrib\sessions\backends\base.py", line 153, in _get_new_session_key
    if not self.exists(session_key):
  File "F:\python3.6.5\lib\site-packages\django\contrib\sessions\backends\db.py", line 45, in exists
    return self.model.objects.filter(session_key=session_key).exists()
  File "F:\python3.6.5\lib\site-packages\django\db\models\query.py", line 715, in exists
    return self.query.has_results(using=self.db)
  File "F:\python3.6.5\lib\site-packages\django\db\models\sql\query.py", line 509, in has_results
    return compiler.has_results()
  File "F:\python3.6.5\lib\site-packages\django\db\models\sql\compiler.py", line 1037, in has_results
    return bool(self.execute_sql(SINGLE))
  File "F:\python3.6.5\lib\site-packages\django\db\models\sql\compiler.py", line 1068, in execute_sql
    cursor.execute(sql, params)
  File "F:\python3.6.5\lib\site-packages\django\db\backends\utils.py", line 100, in execute
    return super().execute(sql, params)
  File "F:\python3.6.5\lib\site-packages\django\db\backends\utils.py", line 68, in execute
    return self._execute_with_wrappers(sql, params, many=False, executor=self._execute)
  File "F:\python3.6.5\lib\site-packages\django\db\backends\utils.py", line 77, in _execute_with_wrappers
    return executor(sql, params, many, context)
  File "F:\python3.6.5\lib\site-packages\django\db\backends\utils.py", line 85, in _execute
    return self.cursor.execute(sql, params)
  File "F:\python3.6.5\lib\site-packages\django\db\utils.py", line 89, in __exit__
    raise dj_exc_value.with_traceback(traceback) from exc_value
  File "F:\python3.6.5\lib\site-packages\django\db\backends\utils.py", line 85, in _execute
    return self.cursor.execute(sql, params)
  File "F:\python3.6.5\lib\site-packages\django\db\backends\sqlite3\base.py", line 303, in execute
    return Database.Cursor.execute(self, query, params)
django.db.utils.OperationalError: no such table: django_session
2018-11-22 00:37:47,526 - ERROR----  Internal Server Error: /add/case/
Traceback (most recent call last):
  File "F:\python3.6.5\lib\site-packages\django\db\backends\utils.py", line 85, in _execute
    return self.cursor.execute(sql, params)
  File "F:\python3.6.5\lib\site-packages\django\db\backends\sqlite3\base.py", line 303, in execute
    return Database.Cursor.execute(self, query, params)
sqlite3.OperationalError: no such table: django_session

The above exception was the direct cause of the following exception:

Traceback (most recent call last):
  File "F:\python3.6.5\lib\site-packages\django\core\handlers\exception.py", line 35, in inner
    response = get_response(request)
  File "F:\python3.6.5\lib\site-packages\django\utils\deprecation.py", line 97, in __call__
    response = self.process_response(request, response)
  File "F:\python3.6.5\lib\site-packages\django\contrib\sessions\middleware.py", line 58, in process_response
    request.session.save()
  File "F:\python3.6.5\lib\site-packages\django\contrib\sessions\backends\db.py", line 79, in save
    return self.create()
  File "F:\python3.6.5\lib\site-packages\django\contrib\sessions\backends\db.py", line 49, in create
    self._session_key = self._get_new_session_key()
  File "F:\python3.6.5\lib\site-packages\django\contrib\sessions\backends\base.py", line 153, in _get_new_session_key
    if not self.exists(session_key):
  File "F:\python3.6.5\lib\site-packages\django\contrib\sessions\backends\db.py", line 45, in exists
    return self.model.objects.filter(session_key=session_key).exists()
  File "F:\python3.6.5\lib\site-packages\django\db\models\query.py", line 715, in exists
    return self.query.has_results(using=self.db)
  File "F:\python3.6.5\lib\site-packages\django\db\models\sql\query.py", line 509, in has_results
    return compiler.has_results()
  File "F:\python3.6.5\lib\site-packages\django\db\models\sql\compiler.py", line 1037, in has_results
    return bool(self.execute_sql(SINGLE))
  File "F:\python3.6.5\lib\site-packages\django\db\models\sql\compiler.py", line 1068, in execute_sql
    cursor.execute(sql, params)
  File "F:\python3.6.5\lib\site-packages\django\db\backends\utils.py", line 100, in execute
    return super().execute(sql, params)
  File "F:\python3.6.5\lib\site-packages\django\db\backends\utils.py", line 68, in execute
    return self._execute_with_wrappers(sql, params, many=False, executor=self._execute)
  File "F:\python3.6.5\lib\site-packages\django\db\backends\utils.py", line 77, in _execute_with_wrappers
    return executor(sql, params, many, context)
  File "F:\python3.6.5\lib\site-packages\django\db\backends\utils.py", line 85, in _execute
    return self.cursor.execute(sql, params)
  File "F:\python3.6.5\lib\site-packages\django\db\utils.py", line 89, in __exit__
    raise dj_exc_value.with_traceback(traceback) from exc_value
  File "F:\python3.6.5\lib\site-packages\django\db\backends\utils.py", line 85, in _execute
    return self.cursor.execute(sql, params)
  File "F:\python3.6.5\lib\site-packages\django\db\backends\sqlite3\base.py", line 303, in execute
    return Database.Cursor.execute(self, query, params)
django.db.utils.OperationalError: no such table: django_session
2018-11-22 00:37:47,778 - ERROR----  Internal Server Error: /add/case/
Traceback (most recent call last):
  File "F:\python3.6.5\lib\site-packages\django\db\backends\utils.py", line 85, in _execute
    return self.cursor.execute(sql, params)
  File "F:\python3.6.5\lib\site-packages\django\db\backends\sqlite3\base.py", line 303, in execute
    return Database.Cursor.execute(self, query, params)
sqlite3.OperationalError: no such table: django_session

The above exception was the direct cause of the following exception:

Traceback (most recent call last):
  File "F:\python3.6.5\lib\site-packages\django\core\handlers\exception.py", line 35, in inner
    response = get_response(request)
  File "F:\python3.6.5\lib\site-packages\django\utils\deprecation.py", line 97, in __call__
    response = self.process_response(request, response)
  File "F:\python3.6.5\lib\site-packages\django\contrib\sessions\middleware.py", line 58, in process_response
    request.session.save()
  File "F:\python3.6.5\lib\site-packages\django\contrib\sessions\backends\db.py", line 79, in save
    return self.create()
  File "F:\python3.6.5\lib\site-packages\django\contrib\sessions\backends\db.py", line 49, in create
    self._session_key = self._get_new_session_key()
  File "F:\python3.6.5\lib\site-packages\django\contrib\sessions\backends\base.py", line 153, in _get_new_session_key
    if not self.exists(session_key):
  File "F:\python3.6.5\lib\site-packages\django\contrib\sessions\backends\db.py", line 45, in exists
    return self.model.objects.filter(session_key=session_key).exists()
  File "F:\python3.6.5\lib\site-packages\django\db\models\query.py", line 715, in exists
    return self.query.has_results(using=self.db)
  File "F:\python3.6.5\lib\site-packages\django\db\models\sql\query.py", line 509, in has_results
    return compiler.has_results()
  File "F:\python3.6.5\lib\site-packages\django\db\models\sql\compiler.py", line 1037, in has_results
    return bool(self.execute_sql(SINGLE))
  File "F:\python3.6.5\lib\site-packages\django\db\models\sql\compiler.py", line 1068, in execute_sql
    cursor.execute(sql, params)
  File "F:\python3.6.5\lib\site-packages\django\db\backends\utils.py", line 100, in execute
    return super().execute(sql, params)
  File "F:\python3.6.5\lib\site-packages\django\db\backends\utils.py", line 68, in execute
    return self._execute_with_wrappers(sql, params, many=False, executor=self._execute)
  File "F:\python3.6.5\lib\site-packages\django\db\backends\utils.py", line 77, in _execute_with_wrappers
    return executor(sql, params, many, context)
  File "F:\python3.6.5\lib\site-packages\django\db\backends\utils.py", line 85, in _execute
    return self.cursor.execute(sql, params)
  File "F:\python3.6.5\lib\site-packages\django\db\utils.py", line 89, in __exit__
    raise dj_exc_value.with_traceback(traceback) from exc_value
  File "F:\python3.6.5\lib\site-packages\django\db\backends\utils.py", line 85, in _execute
    return self.cursor.execute(sql, params)
  File "F:\python3.6.5\lib\site-packages\django\db\backends\sqlite3\base.py", line 303, in execute
    return Database.Cursor.execute(self, query, params)
django.db.utils.OperationalError: no such table: django_session
2018-11-22 00:37:47,966 - ERROR----  Internal Server Error: /add/case/
Traceback (most recent call last):
  File "F:\python3.6.5\lib\site-packages\django\db\backends\utils.py", line 85, in _execute
    return self.cursor.execute(sql, params)
  File "F:\python3.6.5\lib\site-packages\django\db\backends\sqlite3\base.py", line 303, in execute
    return Database.Cursor.execute(self, query, params)
sqlite3.OperationalError: no such table: django_session

The above exception was the direct cause of the following exception:

Traceback (most recent call last):
  File "F:\python3.6.5\lib\site-packages\django\core\handlers\exception.py", line 35, in inner
    response = get_response(request)
  File "F:\python3.6.5\lib\site-packages\django\utils\deprecation.py", line 97, in __call__
    response = self.process_response(request, response)
  File "F:\python3.6.5\lib\site-packages\django\contrib\sessions\middleware.py", line 58, in process_response
    request.session.save()
  File "F:\python3.6.5\lib\site-packages\django\contrib\sessions\backends\db.py", line 79, in save
    return self.create()
  File "F:\python3.6.5\lib\site-packages\django\contrib\sessions\backends\db.py", line 49, in create
    self._session_key = self._get_new_session_key()
  File "F:\python3.6.5\lib\site-packages\django\contrib\sessions\backends\base.py", line 153, in _get_new_session_key
    if not self.exists(session_key):
  File "F:\python3.6.5\lib\site-packages\django\contrib\sessions\backends\db.py", line 45, in exists
    return self.model.objects.filter(session_key=session_key).exists()
  File "F:\python3.6.5\lib\site-packages\django\db\models\query.py", line 715, in exists
    return self.query.has_results(using=self.db)
  File "F:\python3.6.5\lib\site-packages\django\db\models\sql\query.py", line 509, in has_results
    return compiler.has_results()
  File "F:\python3.6.5\lib\site-packages\django\db\models\sql\compiler.py", line 1037, in has_results
    return bool(self.execute_sql(SINGLE))
  File "F:\python3.6.5\lib\site-packages\django\db\models\sql\compiler.py", line 1068, in execute_sql
    cursor.execute(sql, params)
  File "F:\python3.6.5\lib\site-packages\django\db\backends\utils.py", line 100, in execute
    return super().execute(sql, params)
  File "F:\python3.6.5\lib\site-packages\django\db\backends\utils.py", line 68, in execute
    return self._execute_with_wrappers(sql, params, many=False, executor=self._execute)
  File "F:\python3.6.5\lib\site-packages\django\db\backends\utils.py", line 77, in _execute_with_wrappers
    return executor(sql, params, many, context)
  File "F:\python3.6.5\lib\site-packages\django\db\backends\utils.py", line 85, in _execute
    return self.cursor.execute(sql, params)
  File "F:\python3.6.5\lib\site-packages\django\db\utils.py", line 89, in __exit__
    raise dj_exc_value.with_traceback(traceback) from exc_value
  File "F:\python3.6.5\lib\site-packages\django\db\backends\utils.py", line 85, in _execute
    return self.cursor.execute(sql, params)
  File "F:\python3.6.5\lib\site-packages\django\db\backends\sqlite3\base.py", line 303, in execute
    return Database.Cursor.execute(self, query, params)
django.db.utils.OperationalError: no such table: django_session
2018-11-22 00:37:48,190 - ERROR----  Internal Server Error: /add/case/
Traceback (most recent call last):
  File "F:\python3.6.5\lib\site-packages\django\db\backends\utils.py", line 85, in _execute
    return self.cursor.execute(sql, params)
  File "F:\python3.6.5\lib\site-packages\django\db\backends\sqlite3\base.py", line 303, in execute
    return Database.Cursor.execute(self, query, params)
sqlite3.OperationalError: no such table: django_session

The above exception was the direct cause of the following exception:

Traceback (most recent call last):
  File "F:\python3.6.5\lib\site-packages\django\core\handlers\exception.py", line 35, in inner
    response = get_response(request)
  File "F:\python3.6.5\lib\site-packages\django\utils\deprecation.py", line 97, in __call__
    response = self.process_response(request, response)
  File "F:\python3.6.5\lib\site-packages\django\contrib\sessions\middleware.py", line 58, in process_response
    request.session.save()
  File "F:\python3.6.5\lib\site-packages\django\contrib\sessions\backends\db.py", line 79, in save
    return self.create()
  File "F:\python3.6.5\lib\site-packages\django\contrib\sessions\backends\db.py", line 49, in create
    self._session_key = self._get_new_session_key()
  File "F:\python3.6.5\lib\site-packages\django\contrib\sessions\backends\base.py", line 153, in _get_new_session_key
    if not self.exists(session_key):
  File "F:\python3.6.5\lib\site-packages\django\contrib\sessions\backends\db.py", line 45, in exists
    return self.model.objects.filter(session_key=session_key).exists()
  File "F:\python3.6.5\lib\site-packages\django\db\models\query.py", line 715, in exists
    return self.query.has_results(using=self.db)
  File "F:\python3.6.5\lib\site-packages\django\db\models\sql\query.py", line 509, in has_results
    return compiler.has_results()
  File "F:\python3.6.5\lib\site-packages\django\db\models\sql\compiler.py", line 1037, in has_results
    return bool(self.execute_sql(SINGLE))
  File "F:\python3.6.5\lib\site-packages\django\db\models\sql\compiler.py", line 1068, in execute_sql
    cursor.execute(sql, params)
  File "F:\python3.6.5\lib\site-packages\django\db\backends\utils.py", line 100, in execute
    return super().execute(sql, params)
  File "F:\python3.6.5\lib\site-packages\django\db\backends\utils.py", line 68, in execute
    return self._execute_with_wrappers(sql, params, many=False, executor=self._execute)
  File "F:\python3.6.5\lib\site-packages\django\db\backends\utils.py", line 77, in _execute_with_wrappers
    return executor(sql, params, many, context)
  File "F:\python3.6.5\lib\site-packages\django\db\backends\utils.py", line 85, in _execute
    return self.cursor.execute(sql, params)
  File "F:\python3.6.5\lib\site-packages\django\db\utils.py", line 89, in __exit__
    raise dj_exc_value.with_traceback(traceback) from exc_value
  File "F:\python3.6.5\lib\site-packages\django\db\backends\utils.py", line 85, in _execute
    return self.cursor.execute(sql, params)
  File "F:\python3.6.5\lib\site-packages\django\db\backends\sqlite3\base.py", line 303, in execute
    return Database.Cursor.execute(self, query, params)
django.db.utils.OperationalError: no such table: django_session
2018-11-22 00:37:50,301 - INFO----  ------------------------------------------------------------------
2018-11-22 00:37:50,302 - INFO----  当前运行文件：F:/pythonProject/AutoDot\common\GetProjectName.py
2018-11-22 00:37:50,302 - INFO----  F:\pythonProject\AutoDot\case文件下的用例文件 ['自动干线.xlsx']
2018-11-22 00:37:50,357 - INFO----  ------------------------------------------------------------------
2018-11-22 00:37:50,357 - INFO----  当前运行文件：F:/pythonProject/AutoDot\common\GetProjectName.py
2018-11-22 00:37:50,358 - INFO----  F:\pythonProject\AutoDot\case文件下的用例文件 ['自动干线.xlsx']
2018-11-22 00:37:52,378 - INFO----  ------------------------------------------------------------------
2018-11-22 00:37:52,378 - INFO----  当前运行文件：F:/pythonProject/AutoDot\common\GetProjectCase.py
2018-11-22 00:37:52,378 - INFO----  准备获取 自动干线 项目的用例路径
2018-11-22 00:37:52,379 - INFO----  获取到 自动干线 项目的用例路径：F:\pythonProject\AutoDot\case\自动干线.xlsx
2018-11-22 00:37:52,384 - INFO----  获取用例的标题：['ID', 'Run', 'Sort', 'Sql', 'ModuleName', 'CaseName', 'CaseDescription', 'Protocol', 'Host', 'Method', 'Headers', 'Path', 'Data', 'Files', 'ReplaceID', 'Expect', 'CheckPoint', 'Response', 'TransmitID', 'TransmitTargetID', 'Remark', 'CreateDate', 'UpdateTime', 'Author', 'Editor', 'RunResult']
2018-11-22 00:37:53,330 - ERROR----  Internal Server Error: /add/case/
Traceback (most recent call last):
  File "F:\python3.6.5\lib\site-packages\django\db\backends\utils.py", line 85, in _execute
    return self.cursor.execute(sql, params)
  File "F:\python3.6.5\lib\site-packages\django\db\backends\sqlite3\base.py", line 303, in execute
    return Database.Cursor.execute(self, query, params)
sqlite3.OperationalError: no such table: django_session

The above exception was the direct cause of the following exception:

Traceback (most recent call last):
  File "F:\python3.6.5\lib\site-packages\django\core\handlers\exception.py", line 35, in inner
    response = get_response(request)
  File "F:\python3.6.5\lib\site-packages\django\utils\deprecation.py", line 97, in __call__
    response = self.process_response(request, response)
  File "F:\python3.6.5\lib\site-packages\django\contrib\sessions\middleware.py", line 58, in process_response
    request.session.save()
  File "F:\python3.6.5\lib\site-packages\django\contrib\sessions\backends\db.py", line 79, in save
    return self.create()
  File "F:\python3.6.5\lib\site-packages\django\contrib\sessions\backends\db.py", line 49, in create
    self._session_key = self._get_new_session_key()
  File "F:\python3.6.5\lib\site-packages\django\contrib\sessions\backends\base.py", line 153, in _get_new_session_key
    if not self.exists(session_key):
  File "F:\python3.6.5\lib\site-packages\django\contrib\sessions\backends\db.py", line 45, in exists
    return self.model.objects.filter(session_key=session_key).exists()
  File "F:\python3.6.5\lib\site-packages\django\db\models\query.py", line 715, in exists
    return self.query.has_results(using=self.db)
  File "F:\python3.6.5\lib\site-packages\django\db\models\sql\query.py", line 509, in has_results
    return compiler.has_results()
  File "F:\python3.6.5\lib\site-packages\django\db\models\sql\compiler.py", line 1037, in has_results
    return bool(self.execute_sql(SINGLE))
  File "F:\python3.6.5\lib\site-packages\django\db\models\sql\compiler.py", line 1068, in execute_sql
    cursor.execute(sql, params)
  File "F:\python3.6.5\lib\site-packages\django\db\backends\utils.py", line 100, in execute
    return super().execute(sql, params)
  File "F:\python3.6.5\lib\site-packages\django\db\backends\utils.py", line 68, in execute
    return self._execute_with_wrappers(sql, params, many=False, executor=self._execute)
  File "F:\python3.6.5\lib\site-packages\django\db\backends\utils.py", line 77, in _execute_with_wrappers
    return executor(sql, params, many, context)
  File "F:\python3.6.5\lib\site-packages\django\db\backends\utils.py", line 85, in _execute
    return self.cursor.execute(sql, params)
  File "F:\python3.6.5\lib\site-packages\django\db\utils.py", line 89, in __exit__
    raise dj_exc_value.with_traceback(traceback) from exc_value
  File "F:\python3.6.5\lib\site-packages\django\db\backends\utils.py", line 85, in _execute
    return self.cursor.execute(sql, params)
  File "F:\python3.6.5\lib\site-packages\django\db\backends\sqlite3\base.py", line 303, in execute
    return Database.Cursor.execute(self, query, params)
django.db.utils.OperationalError: no such table: django_session
2018-11-22 00:37:53,751 - ERROR----  Internal Server Error: /add/case/
Traceback (most recent call last):
  File "F:\python3.6.5\lib\site-packages\django\db\backends\utils.py", line 85, in _execute
    return self.cursor.execute(sql, params)
  File "F:\python3.6.5\lib\site-packages\django\db\backends\sqlite3\base.py", line 303, in execute
    return Database.Cursor.execute(self, query, params)
sqlite3.OperationalError: no such table: django_session

The above exception was the direct cause of the following exception:

Traceback (most recent call last):
  File "F:\python3.6.5\lib\site-packages\django\core\handlers\exception.py", line 35, in inner
    response = get_response(request)
  File "F:\python3.6.5\lib\site-packages\django\utils\deprecation.py", line 97, in __call__
    response = self.process_response(request, response)
  File "F:\python3.6.5\lib\site-packages\django\contrib\sessions\middleware.py", line 58, in process_response
    request.session.save()
  File "F:\python3.6.5\lib\site-packages\django\contrib\sessions\backends\db.py", line 79, in save
    return self.create()
  File "F:\python3.6.5\lib\site-packages\django\contrib\sessions\backends\db.py", line 49, in create
    self._session_key = self._get_new_session_key()
  File "F:\python3.6.5\lib\site-packages\django\contrib\sessions\backends\base.py", line 153, in _get_new_session_key
    if not self.exists(session_key):
  File "F:\python3.6.5\lib\site-packages\django\contrib\sessions\backends\db.py", line 45, in exists
    return self.model.objects.filter(session_key=session_key).exists()
  File "F:\python3.6.5\lib\site-packages\django\db\models\query.py", line 715, in exists
    return self.query.has_results(using=self.db)
  File "F:\python3.6.5\lib\site-packages\django\db\models\sql\query.py", line 509, in has_results
    return compiler.has_results()
  File "F:\python3.6.5\lib\site-packages\django\db\models\sql\compiler.py", line 1037, in has_results
    return bool(self.execute_sql(SINGLE))
  File "F:\python3.6.5\lib\site-packages\django\db\models\sql\compiler.py", line 1068, in execute_sql
    cursor.execute(sql, params)
  File "F:\python3.6.5\lib\site-packages\django\db\backends\utils.py", line 100, in execute
    return super().execute(sql, params)
  File "F:\python3.6.5\lib\site-packages\django\db\backends\utils.py", line 68, in execute
    return self._execute_with_wrappers(sql, params, many=False, executor=self._execute)
  File "F:\python3.6.5\lib\site-packages\django\db\backends\utils.py", line 77, in _execute_with_wrappers
    return executor(sql, params, many, context)
  File "F:\python3.6.5\lib\site-packages\django\db\backends\utils.py", line 85, in _execute
    return self.cursor.execute(sql, params)
  File "F:\python3.6.5\lib\site-packages\django\db\utils.py", line 89, in __exit__
    raise dj_exc_value.with_traceback(traceback) from exc_value
  File "F:\python3.6.5\lib\site-packages\django\db\backends\utils.py", line 85, in _execute
    return self.cursor.execute(sql, params)
  File "F:\python3.6.5\lib\site-packages\django\db\backends\sqlite3\base.py", line 303, in execute
    return Database.Cursor.execute(self, query, params)
django.db.utils.OperationalError: no such table: django_session
2018-11-22 00:37:53,826 - ERROR----  Internal Server Error: /add/case/
Traceback (most recent call last):
  File "F:\python3.6.5\lib\site-packages\django\db\backends\utils.py", line 85, in _execute
    return self.cursor.execute(sql, params)
  File "F:\python3.6.5\lib\site-packages\django\db\backends\sqlite3\base.py", line 303, in execute
    return Database.Cursor.execute(self, query, params)
sqlite3.OperationalError: no such table: django_session

The above exception was the direct cause of the following exception:

Traceback (most recent call last):
  File "F:\python3.6.5\lib\site-packages\django\core\handlers\exception.py", line 35, in inner
    response = get_response(request)
  File "F:\python3.6.5\lib\site-packages\django\utils\deprecation.py", line 97, in __call__
    response = self.process_response(request, response)
  File "F:\python3.6.5\lib\site-packages\django\contrib\sessions\middleware.py", line 58, in process_response
    request.session.save()
  File "F:\python3.6.5\lib\site-packages\django\contrib\sessions\backends\db.py", line 79, in save
    return self.create()
  File "F:\python3.6.5\lib\site-packages\django\contrib\sessions\backends\db.py", line 49, in create
    self._session_key = self._get_new_session_key()
  File "F:\python3.6.5\lib\site-packages\django\contrib\sessions\backends\base.py", line 153, in _get_new_session_key
    if not self.exists(session_key):
  File "F:\python3.6.5\lib\site-packages\django\contrib\sessions\backends\db.py", line 45, in exists
    return self.model.objects.filter(session_key=session_key).exists()
  File "F:\python3.6.5\lib\site-packages\django\db\models\query.py", line 715, in exists
    return self.query.has_results(using=self.db)
  File "F:\python3.6.5\lib\site-packages\django\db\models\sql\query.py", line 509, in has_results
    return compiler.has_results()
  File "F:\python3.6.5\lib\site-packages\django\db\models\sql\compiler.py", line 1037, in has_results
    return bool(self.execute_sql(SINGLE))
  File "F:\python3.6.5\lib\site-packages\django\db\models\sql\compiler.py", line 1068, in execute_sql
    cursor.execute(sql, params)
  File "F:\python3.6.5\lib\site-packages\django\db\backends\utils.py", line 100, in execute
    return super().execute(sql, params)
  File "F:\python3.6.5\lib\site-packages\django\db\backends\utils.py", line 68, in execute
    return self._execute_with_wrappers(sql, params, many=False, executor=self._execute)
  File "F:\python3.6.5\lib\site-packages\django\db\backends\utils.py", line 77, in _execute_with_wrappers
    return executor(sql, params, many, context)
  File "F:\python3.6.5\lib\site-packages\django\db\backends\utils.py", line 85, in _execute
    return self.cursor.execute(sql, params)
  File "F:\python3.6.5\lib\site-packages\django\db\utils.py", line 89, in __exit__
    raise dj_exc_value.with_traceback(traceback) from exc_value
  File "F:\python3.6.5\lib\site-packages\django\db\backends\utils.py", line 85, in _execute
    return self.cursor.execute(sql, params)
  File "F:\python3.6.5\lib\site-packages\django\db\backends\sqlite3\base.py", line 303, in execute
    return Database.Cursor.execute(self, query, params)
django.db.utils.OperationalError: no such table: django_session
2018-11-22 00:37:55,090 - INFO----  ------------------------------------------------------------------
2018-11-22 00:37:55,090 - INFO----  当前运行文件：F:/pythonProject/AutoDot\common\GetProjectCase.py
2018-11-22 00:37:55,091 - INFO----  准备获取 自动干线 项目的用例路径
2018-11-22 00:37:55,091 - INFO----  获取到 自动干线 项目的用例路径：F:\pythonProject\AutoDot\case\自动干线.xlsx
2018-11-22 00:37:55,096 - INFO----  获取用例的标题：['ID', 'Run', 'Sort', 'Sql', 'ModuleName', 'CaseName', 'CaseDescription', 'Protocol', 'Host', 'Method', 'Headers', 'Path', 'Data', 'Files', 'ReplaceID', 'Expect', 'CheckPoint', 'Response', 'TransmitID', 'TransmitTargetID', 'Remark', 'CreateDate', 'UpdateTime', 'Author', 'Editor', 'RunResult']
2018-11-22 00:38:27,805 - INFO----  ------------------------------------------------------------------
2018-11-22 00:38:27,806 - INFO----  当前运行文件：F:/pythonProject/AutoDot\common\GetProjectName.py
2018-11-22 00:38:27,807 - INFO----  F:\pythonProject\AutoDot\case文件下的用例文件 ['自动干线.xlsx']
2018-11-22 00:38:27,867 - INFO----  ------------------------------------------------------------------
2018-11-22 00:38:27,867 - INFO----  当前运行文件：F:/pythonProject/AutoDot\common\GetProjectName.py
2018-11-22 00:38:27,867 - INFO----  F:\pythonProject\AutoDot\case文件下的用例文件 ['自动干线.xlsx']
2018-11-22 00:38:29,776 - INFO----  ------------------------------------------------------------------
2018-11-22 00:38:29,776 - INFO----  当前运行文件：F:/pythonProject/AutoDot\common\GetProjectCase.py
2018-11-22 00:38:29,777 - INFO----  准备获取 自动干线 项目的用例路径
2018-11-22 00:38:29,777 - INFO----  获取到 自动干线 项目的用例路径：F:\pythonProject\AutoDot\case\自动干线.xlsx
2018-11-22 00:38:29,781 - INFO----  获取用例的标题：['ID', 'Run', 'Sort', 'Sql', 'ModuleName', 'CaseName', 'CaseDescription', 'Protocol', 'Host', 'Method', 'Headers', 'Path', 'Data', 'Files', 'ReplaceID', 'Expect', 'CheckPoint', 'Response', 'TransmitID', 'TransmitTargetID', 'Remark', 'CreateDate', 'UpdateTime', 'Author', 'Editor', 'RunResult']
2018-11-22 00:38:30,840 - ERROR----  Internal Server Error: /add/case/
Traceback (most recent call last):
  File "F:\python3.6.5\lib\site-packages\django\contrib\sessions\backends\base.py", line 191, in _get_session
    return self._session_cache
AttributeError: 'SessionStore' object has no attribute '_session_cache'

During handling of the above exception, another exception occurred:

Traceback (most recent call last):
  File "F:\python3.6.5\lib\site-packages\django\db\backends\utils.py", line 85, in _execute
    return self.cursor.execute(sql, params)
  File "F:\python3.6.5\lib\site-packages\django\db\backends\sqlite3\base.py", line 303, in execute
    return Database.Cursor.execute(self, query, params)
sqlite3.OperationalError: no such table: django_session

The above exception was the direct cause of the following exception:

Traceback (most recent call last):
  File "F:\python3.6.5\lib\site-packages\django\core\handlers\exception.py", line 35, in inner
    response = get_response(request)
  File "F:\python3.6.5\lib\site-packages\django\core\handlers\base.py", line 128, in _get_response
    response = self.process_exception_by_middleware(e, request)
  File "F:\python3.6.5\lib\site-packages\django\core\handlers\base.py", line 126, in _get_response
    response = wrapped_callback(request, *callback_args, **callback_kwargs)
  File "F:/pythonProject/AutoDot\DotDotDot\views.py", line 159, in add_case_page
    request.session['msg'] = context
  File "F:\python3.6.5\lib\site-packages\django\contrib\sessions\backends\base.py", line 58, in __setitem__
    self._session[key] = value
  File "F:\python3.6.5\lib\site-packages\django\contrib\sessions\backends\base.py", line 196, in _get_session
    self._session_cache = self.load()
  File "F:\python3.6.5\lib\site-packages\django\contrib\sessions\backends\db.py", line 34, in load
    expire_date__gt=timezone.now()
  File "F:\python3.6.5\lib\site-packages\django\db\models\manager.py", line 82, in manager_method
    return getattr(self.get_queryset(), name)(*args, **kwargs)
  File "F:\python3.6.5\lib\site-packages\django\db\models\query.py", line 397, in get
    num = len(clone)
  File "F:\python3.6.5\lib\site-packages\django\db\models\query.py", line 254, in __len__
    self._fetch_all()
  File "F:\python3.6.5\lib\site-packages\django\db\models\query.py", line 1179, in _fetch_all
    self._result_cache = list(self._iterable_class(self))
  File "F:\python3.6.5\lib\site-packages\django\db\models\query.py", line 53, in __iter__
    results = compiler.execute_sql(chunked_fetch=self.chunked_fetch, chunk_size=self.chunk_size)
  File "F:\python3.6.5\lib\site-packages\django\db\models\sql\compiler.py", line 1068, in execute_sql
    cursor.execute(sql, params)
  File "F:\python3.6.5\lib\site-packages\django\db\backends\utils.py", line 100, in execute
    return super().execute(sql, params)
  File "F:\python3.6.5\lib\site-packages\django\db\backends\utils.py", line 68, in execute
    return self._execute_with_wrappers(sql, params, many=False, executor=self._execute)
  File "F:\python3.6.5\lib\site-packages\django\db\backends\utils.py", line 77, in _execute_with_wrappers
    return executor(sql, params, many, context)
  File "F:\python3.6.5\lib\site-packages\django\db\backends\utils.py", line 85, in _execute
    return self.cursor.execute(sql, params)
  File "F:\python3.6.5\lib\site-packages\django\db\utils.py", line 89, in __exit__
    raise dj_exc_value.with_traceback(traceback) from exc_value
  File "F:\python3.6.5\lib\site-packages\django\db\backends\utils.py", line 85, in _execute
    return self.cursor.execute(sql, params)
  File "F:\python3.6.5\lib\site-packages\django\db\backends\sqlite3\base.py", line 303, in execute
    return Database.Cursor.execute(self, query, params)
django.db.utils.OperationalError: no such table: django_session
2018-11-22 00:38:31,622 - ERROR----  Internal Server Error: /add/case/
Traceback (most recent call last):
  File "F:\python3.6.5\lib\site-packages\django\contrib\sessions\backends\base.py", line 191, in _get_session
    return self._session_cache
AttributeError: 'SessionStore' object has no attribute '_session_cache'

During handling of the above exception, another exception occurred:

Traceback (most recent call last):
  File "F:\python3.6.5\lib\site-packages\django\db\backends\utils.py", line 85, in _execute
    return self.cursor.execute(sql, params)
  File "F:\python3.6.5\lib\site-packages\django\db\backends\sqlite3\base.py", line 303, in execute
    return Database.Cursor.execute(self, query, params)
sqlite3.OperationalError: no such table: django_session

The above exception was the direct cause of the following exception:

Traceback (most recent call last):
  File "F:\python3.6.5\lib\site-packages\django\core\handlers\exception.py", line 35, in inner
    response = get_response(request)
  File "F:\python3.6.5\lib\site-packages\django\core\handlers\base.py", line 128, in _get_response
    response = self.process_exception_by_middleware(e, request)
  File "F:\python3.6.5\lib\site-packages\django\core\handlers\base.py", line 126, in _get_response
    response = wrapped_callback(request, *callback_args, **callback_kwargs)
  File "F:/pythonProject/AutoDot\DotDotDot\views.py", line 159, in add_case_page
    request.session['msg'] = context
  File "F:\python3.6.5\lib\site-packages\django\contrib\sessions\backends\base.py", line 58, in __setitem__
    self._session[key] = value
  File "F:\python3.6.5\lib\site-packages\django\contrib\sessions\backends\base.py", line 196, in _get_session
    self._session_cache = self.load()
  File "F:\python3.6.5\lib\site-packages\django\contrib\sessions\backends\db.py", line 34, in load
    expire_date__gt=timezone.now()
  File "F:\python3.6.5\lib\site-packages\django\db\models\manager.py", line 82, in manager_method
    return getattr(self.get_queryset(), name)(*args, **kwargs)
  File "F:\python3.6.5\lib\site-packages\django\db\models\query.py", line 397, in get
    num = len(clone)
  File "F:\python3.6.5\lib\site-packages\django\db\models\query.py", line 254, in __len__
    self._fetch_all()
  File "F:\python3.6.5\lib\site-packages\django\db\models\query.py", line 1179, in _fetch_all
    self._result_cache = list(self._iterable_class(self))
  File "F:\python3.6.5\lib\site-packages\django\db\models\query.py", line 53, in __iter__
    results = compiler.execute_sql(chunked_fetch=self.chunked_fetch, chunk_size=self.chunk_size)
  File "F:\python3.6.5\lib\site-packages\django\db\models\sql\compiler.py", line 1068, in execute_sql
    cursor.execute(sql, params)
  File "F:\python3.6.5\lib\site-packages\django\db\backends\utils.py", line 100, in execute
    return super().execute(sql, params)
  File "F:\python3.6.5\lib\site-packages\django\db\backends\utils.py", line 68, in execute
    return self._execute_with_wrappers(sql, params, many=False, executor=self._execute)
  File "F:\python3.6.5\lib\site-packages\django\db\backends\utils.py", line 77, in _execute_with_wrappers
    return executor(sql, params, many, context)
  File "F:\python3.6.5\lib\site-packages\django\db\backends\utils.py", line 85, in _execute
    return self.cursor.execute(sql, params)
  File "F:\python3.6.5\lib\site-packages\django\db\utils.py", line 89, in __exit__
    raise dj_exc_value.with_traceback(traceback) from exc_value
  File "F:\python3.6.5\lib\site-packages\django\db\backends\utils.py", line 85, in _execute
    return self.cursor.execute(sql, params)
  File "F:\python3.6.5\lib\site-packages\django\db\backends\sqlite3\base.py", line 303, in execute
    return Database.Cursor.execute(self, query, params)
django.db.utils.OperationalError: no such table: django_session
2018-11-22 00:38:31,846 - ERROR----  Internal Server Error: /add/case/
Traceback (most recent call last):
  File "F:\python3.6.5\lib\site-packages\django\contrib\sessions\backends\base.py", line 191, in _get_session
    return self._session_cache
AttributeError: 'SessionStore' object has no attribute '_session_cache'

During handling of the above exception, another exception occurred:

Traceback (most recent call last):
  File "F:\python3.6.5\lib\site-packages\django\db\backends\utils.py", line 85, in _execute
    return self.cursor.execute(sql, params)
  File "F:\python3.6.5\lib\site-packages\django\db\backends\sqlite3\base.py", line 303, in execute
    return Database.Cursor.execute(self, query, params)
sqlite3.OperationalError: no such table: django_session

The above exception was the direct cause of the following exception:

Traceback (most recent call last):
  File "F:\python3.6.5\lib\site-packages\django\core\handlers\exception.py", line 35, in inner
    response = get_response(request)
  File "F:\python3.6.5\lib\site-packages\django\core\handlers\base.py", line 128, in _get_response
    response = self.process_exception_by_middleware(e, request)
  File "F:\python3.6.5\lib\site-packages\django\core\handlers\base.py", line 126, in _get_response
    response = wrapped_callback(request, *callback_args, **callback_kwargs)
  File "F:/pythonProject/AutoDot\DotDotDot\views.py", line 159, in add_case_page
    request.session['msg'] = context
  File "F:\python3.6.5\lib\site-packages\django\contrib\sessions\backends\base.py", line 58, in __setitem__
    self._session[key] = value
  File "F:\python3.6.5\lib\site-packages\django\contrib\sessions\backends\base.py", line 196, in _get_session
    self._session_cache = self.load()
  File "F:\python3.6.5\lib\site-packages\django\contrib\sessions\backends\db.py", line 34, in load
    expire_date__gt=timezone.now()
  File "F:\python3.6.5\lib\site-packages\django\db\models\manager.py", line 82, in manager_method
    return getattr(self.get_queryset(), name)(*args, **kwargs)
  File "F:\python3.6.5\lib\site-packages\django\db\models\query.py", line 397, in get
    num = len(clone)
  File "F:\python3.6.5\lib\site-packages\django\db\models\query.py", line 254, in __len__
    self._fetch_all()
  File "F:\python3.6.5\lib\site-packages\django\db\models\query.py", line 1179, in _fetch_all
    self._result_cache = list(self._iterable_class(self))
  File "F:\python3.6.5\lib\site-packages\django\db\models\query.py", line 53, in __iter__
    results = compiler.execute_sql(chunked_fetch=self.chunked_fetch, chunk_size=self.chunk_size)
  File "F:\python3.6.5\lib\site-packages\django\db\models\sql\compiler.py", line 1068, in execute_sql
    cursor.execute(sql, params)
  File "F:\python3.6.5\lib\site-packages\django\db\backends\utils.py", line 100, in execute
    return super().execute(sql, params)
  File "F:\python3.6.5\lib\site-packages\django\db\backends\utils.py", line 68, in execute
    return self._execute_with_wrappers(sql, params, many=False, executor=self._execute)
  File "F:\python3.6.5\lib\site-packages\django\db\backends\utils.py", line 77, in _execute_with_wrappers
    return executor(sql, params, many, context)
  File "F:\python3.6.5\lib\site-packages\django\db\backends\utils.py", line 85, in _execute
    return self.cursor.execute(sql, params)
  File "F:\python3.6.5\lib\site-packages\django\db\utils.py", line 89, in __exit__
    raise dj_exc_value.with_traceback(traceback) from exc_value
  File "F:\python3.6.5\lib\site-packages\django\db\backends\utils.py", line 85, in _execute
    return self.cursor.execute(sql, params)
  File "F:\python3.6.5\lib\site-packages\django\db\backends\sqlite3\base.py", line 303, in execute
    return Database.Cursor.execute(self, query, params)
django.db.utils.OperationalError: no such table: django_session
2018-11-22 00:38:32,086 - ERROR----  Internal Server Error: /add/case/
Traceback (most recent call last):
  File "F:\python3.6.5\lib\site-packages\django\contrib\sessions\backends\base.py", line 191, in _get_session
    return self._session_cache
AttributeError: 'SessionStore' object has no attribute '_session_cache'

During handling of the above exception, another exception occurred:

Traceback (most recent call last):
  File "F:\python3.6.5\lib\site-packages\django\db\backends\utils.py", line 85, in _execute
    return self.cursor.execute(sql, params)
  File "F:\python3.6.5\lib\site-packages\django\db\backends\sqlite3\base.py", line 303, in execute
    return Database.Cursor.execute(self, query, params)
sqlite3.OperationalError: no such table: django_session

The above exception was the direct cause of the following exception:

Traceback (most recent call last):
  File "F:\python3.6.5\lib\site-packages\django\core\handlers\exception.py", line 35, in inner
    response = get_response(request)
  File "F:\python3.6.5\lib\site-packages\django\core\handlers\base.py", line 128, in _get_response
    response = self.process_exception_by_middleware(e, request)
  File "F:\python3.6.5\lib\site-packages\django\core\handlers\base.py", line 126, in _get_response
    response = wrapped_callback(request, *callback_args, **callback_kwargs)
  File "F:/pythonProject/AutoDot\DotDotDot\views.py", line 159, in add_case_page
    request.session['msg'] = context
  File "F:\python3.6.5\lib\site-packages\django\contrib\sessions\backends\base.py", line 58, in __setitem__
    self._session[key] = value
  File "F:\python3.6.5\lib\site-packages\django\contrib\sessions\backends\base.py", line 196, in _get_session
    self._session_cache = self.load()
  File "F:\python3.6.5\lib\site-packages\django\contrib\sessions\backends\db.py", line 34, in load
    expire_date__gt=timezone.now()
  File "F:\python3.6.5\lib\site-packages\django\db\models\manager.py", line 82, in manager_method
    return getattr(self.get_queryset(), name)(*args, **kwargs)
  File "F:\python3.6.5\lib\site-packages\django\db\models\query.py", line 397, in get
    num = len(clone)
  File "F:\python3.6.5\lib\site-packages\django\db\models\query.py", line 254, in __len__
    self._fetch_all()
  File "F:\python3.6.5\lib\site-packages\django\db\models\query.py", line 1179, in _fetch_all
    self._result_cache = list(self._iterable_class(self))
  File "F:\python3.6.5\lib\site-packages\django\db\models\query.py", line 53, in __iter__
    results = compiler.execute_sql(chunked_fetch=self.chunked_fetch, chunk_size=self.chunk_size)
  File "F:\python3.6.5\lib\site-packages\django\db\models\sql\compiler.py", line 1068, in execute_sql
    cursor.execute(sql, params)
  File "F:\python3.6.5\lib\site-packages\django\db\backends\utils.py", line 100, in execute
    return super().execute(sql, params)
  File "F:\python3.6.5\lib\site-packages\django\db\backends\utils.py", line 68, in execute
    return self._execute_with_wrappers(sql, params, many=False, executor=self._execute)
  File "F:\python3.6.5\lib\site-packages\django\db\backends\utils.py", line 77, in _execute_with_wrappers
    return executor(sql, params, many, context)
  File "F:\python3.6.5\lib\site-packages\django\db\backends\utils.py", line 85, in _execute
    return self.cursor.execute(sql, params)
  File "F:\python3.6.5\lib\site-packages\django\db\utils.py", line 89, in __exit__
    raise dj_exc_value.with_traceback(traceback) from exc_value
  File "F:\python3.6.5\lib\site-packages\django\db\backends\utils.py", line 85, in _execute
    return self.cursor.execute(sql, params)
  File "F:\python3.6.5\lib\site-packages\django\db\backends\sqlite3\base.py", line 303, in execute
    return Database.Cursor.execute(self, query, params)
django.db.utils.OperationalError: no such table: django_session
2018-11-22 00:38:32,343 - ERROR----  Internal Server Error: /add/case/
Traceback (most recent call last):
  File "F:\python3.6.5\lib\site-packages\django\contrib\sessions\backends\base.py", line 191, in _get_session
    return self._session_cache
AttributeError: 'SessionStore' object has no attribute '_session_cache'

During handling of the above exception, another exception occurred:

Traceback (most recent call last):
  File "F:\python3.6.5\lib\site-packages\django\db\backends\utils.py", line 85, in _execute
    return self.cursor.execute(sql, params)
  File "F:\python3.6.5\lib\site-packages\django\db\backends\sqlite3\base.py", line 303, in execute
    return Database.Cursor.execute(self, query, params)
sqlite3.OperationalError: no such table: django_session

The above exception was the direct cause of the following exception:

Traceback (most recent call last):
  File "F:\python3.6.5\lib\site-packages\django\core\handlers\exception.py", line 35, in inner
    response = get_response(request)
  File "F:\python3.6.5\lib\site-packages\django\core\handlers\base.py", line 128, in _get_response
    response = self.process_exception_by_middleware(e, request)
  File "F:\python3.6.5\lib\site-packages\django\core\handlers\base.py", line 126, in _get_response
    response = wrapped_callback(request, *callback_args, **callback_kwargs)
  File "F:/pythonProject/AutoDot\DotDotDot\views.py", line 159, in add_case_page
    request.session['msg'] = context
  File "F:\python3.6.5\lib\site-packages\django\contrib\sessions\backends\base.py", line 58, in __setitem__
    self._session[key] = value
  File "F:\python3.6.5\lib\site-packages\django\contrib\sessions\backends\base.py", line 196, in _get_session
    self._session_cache = self.load()
  File "F:\python3.6.5\lib\site-packages\django\contrib\sessions\backends\db.py", line 34, in load
    expire_date__gt=timezone.now()
  File "F:\python3.6.5\lib\site-packages\django\db\models\manager.py", line 82, in manager_method
    return getattr(self.get_queryset(), name)(*args, **kwargs)
  File "F:\python3.6.5\lib\site-packages\django\db\models\query.py", line 397, in get
    num = len(clone)
  File "F:\python3.6.5\lib\site-packages\django\db\models\query.py", line 254, in __len__
    self._fetch_all()
  File "F:\python3.6.5\lib\site-packages\django\db\models\query.py", line 1179, in _fetch_all
    self._result_cache = list(self._iterable_class(self))
  File "F:\python3.6.5\lib\site-packages\django\db\models\query.py", line 53, in __iter__
    results = compiler.execute_sql(chunked_fetch=self.chunked_fetch, chunk_size=self.chunk_size)
  File "F:\python3.6.5\lib\site-packages\django\db\models\sql\compiler.py", line 1068, in execute_sql
    cursor.execute(sql, params)
  File "F:\python3.6.5\lib\site-packages\django\db\backends\utils.py", line 100, in execute
    return super().execute(sql, params)
  File "F:\python3.6.5\lib\site-packages\django\db\backends\utils.py", line 68, in execute
    return self._execute_with_wrappers(sql, params, many=False, executor=self._execute)
  File "F:\python3.6.5\lib\site-packages\django\db\backends\utils.py", line 77, in _execute_with_wrappers
    return executor(sql, params, many, context)
  File "F:\python3.6.5\lib\site-packages\django\db\backends\utils.py", line 85, in _execute
    return self.cursor.execute(sql, params)
  File "F:\python3.6.5\lib\site-packages\django\db\utils.py", line 89, in __exit__
    raise dj_exc_value.with_traceback(traceback) from exc_value
  File "F:\python3.6.5\lib\site-packages\django\db\backends\utils.py", line 85, in _execute
    return self.cursor.execute(sql, params)
  File "F:\python3.6.5\lib\site-packages\django\db\backends\sqlite3\base.py", line 303, in execute
    return Database.Cursor.execute(self, query, params)
django.db.utils.OperationalError: no such table: django_session
2018-11-22 00:38:33,294 - ERROR----  Internal Server Error: /add/case/
Traceback (most recent call last):
  File "F:\python3.6.5\lib\site-packages\django\contrib\sessions\backends\base.py", line 191, in _get_session
    return self._session_cache
AttributeError: 'SessionStore' object has no attribute '_session_cache'

During handling of the above exception, another exception occurred:

Traceback (most recent call last):
  File "F:\python3.6.5\lib\site-packages\django\db\backends\utils.py", line 85, in _execute
    return self.cursor.execute(sql, params)
  File "F:\python3.6.5\lib\site-packages\django\db\backends\sqlite3\base.py", line 303, in execute
    return Database.Cursor.execute(self, query, params)
sqlite3.OperationalError: no such table: django_session

The above exception was the direct cause of the following exception:

Traceback (most recent call last):
  File "F:\python3.6.5\lib\site-packages\django\core\handlers\exception.py", line 35, in inner
    response = get_response(request)
  File "F:\python3.6.5\lib\site-packages\django\core\handlers\base.py", line 128, in _get_response
    response = self.process_exception_by_middleware(e, request)
  File "F:\python3.6.5\lib\site-packages\django\core\handlers\base.py", line 126, in _get_response
    response = wrapped_callback(request, *callback_args, **callback_kwargs)
  File "F:/pythonProject/AutoDot\DotDotDot\views.py", line 159, in add_case_page
    request.session['msg'] = context
  File "F:\python3.6.5\lib\site-packages\django\contrib\sessions\backends\base.py", line 58, in __setitem__
    self._session[key] = value
  File "F:\python3.6.5\lib\site-packages\django\contrib\sessions\backends\base.py", line 196, in _get_session
    self._session_cache = self.load()
  File "F:\python3.6.5\lib\site-packages\django\contrib\sessions\backends\db.py", line 34, in load
    expire_date__gt=timezone.now()
  File "F:\python3.6.5\lib\site-packages\django\db\models\manager.py", line 82, in manager_method
    return getattr(self.get_queryset(), name)(*args, **kwargs)
  File "F:\python3.6.5\lib\site-packages\django\db\models\query.py", line 397, in get
    num = len(clone)
  File "F:\python3.6.5\lib\site-packages\django\db\models\query.py", line 254, in __len__
    self._fetch_all()
  File "F:\python3.6.5\lib\site-packages\django\db\models\query.py", line 1179, in _fetch_all
    self._result_cache = list(self._iterable_class(self))
  File "F:\python3.6.5\lib\site-packages\django\db\models\query.py", line 53, in __iter__
    results = compiler.execute_sql(chunked_fetch=self.chunked_fetch, chunk_size=self.chunk_size)
  File "F:\python3.6.5\lib\site-packages\django\db\models\sql\compiler.py", line 1068, in execute_sql
    cursor.execute(sql, params)
  File "F:\python3.6.5\lib\site-packages\django\db\backends\utils.py", line 100, in execute
    return super().execute(sql, params)
  File "F:\python3.6.5\lib\site-packages\django\db\backends\utils.py", line 68, in execute
    return self._execute_with_wrappers(sql, params, many=False, executor=self._execute)
  File "F:\python3.6.5\lib\site-packages\django\db\backends\utils.py", line 77, in _execute_with_wrappers
    return executor(sql, params, many, context)
  File "F:\python3.6.5\lib\site-packages\django\db\backends\utils.py", line 85, in _execute
    return self.cursor.execute(sql, params)
  File "F:\python3.6.5\lib\site-packages\django\db\utils.py", line 89, in __exit__
    raise dj_exc_value.with_traceback(traceback) from exc_value
  File "F:\python3.6.5\lib\site-packages\django\db\backends\utils.py", line 85, in _execute
    return self.cursor.execute(sql, params)
  File "F:\python3.6.5\lib\site-packages\django\db\backends\sqlite3\base.py", line 303, in execute
    return Database.Cursor.execute(self, query, params)
django.db.utils.OperationalError: no such table: django_session
2018-11-22 00:38:34,405 - ERROR----  Internal Server Error: /add/case/
Traceback (most recent call last):
  File "F:\python3.6.5\lib\site-packages\django\contrib\sessions\backends\base.py", line 191, in _get_session
    return self._session_cache
AttributeError: 'SessionStore' object has no attribute '_session_cache'

During handling of the above exception, another exception occurred:

Traceback (most recent call last):
  File "F:\python3.6.5\lib\site-packages\django\db\backends\utils.py", line 85, in _execute
    return self.cursor.execute(sql, params)
  File "F:\python3.6.5\lib\site-packages\django\db\backends\sqlite3\base.py", line 303, in execute
    return Database.Cursor.execute(self, query, params)
sqlite3.OperationalError: no such table: django_session

The above exception was the direct cause of the following exception:

Traceback (most recent call last):
  File "F:\python3.6.5\lib\site-packages\django\core\handlers\exception.py", line 35, in inner
    response = get_response(request)
  File "F:\python3.6.5\lib\site-packages\django\core\handlers\base.py", line 128, in _get_response
    response = self.process_exception_by_middleware(e, request)
  File "F:\python3.6.5\lib\site-packages\django\core\handlers\base.py", line 126, in _get_response
    response = wrapped_callback(request, *callback_args, **callback_kwargs)
  File "F:/pythonProject/AutoDot\DotDotDot\views.py", line 159, in add_case_page
    request.session['msg'] = context
  File "F:\python3.6.5\lib\site-packages\django\contrib\sessions\backends\base.py", line 58, in __setitem__
    self._session[key] = value
  File "F:\python3.6.5\lib\site-packages\django\contrib\sessions\backends\base.py", line 196, in _get_session
    self._session_cache = self.load()
  File "F:\python3.6.5\lib\site-packages\django\contrib\sessions\backends\db.py", line 34, in load
    expire_date__gt=timezone.now()
  File "F:\python3.6.5\lib\site-packages\django\db\models\manager.py", line 82, in manager_method
    return getattr(self.get_queryset(), name)(*args, **kwargs)
  File "F:\python3.6.5\lib\site-packages\django\db\models\query.py", line 397, in get
    num = len(clone)
  File "F:\python3.6.5\lib\site-packages\django\db\models\query.py", line 254, in __len__
    self._fetch_all()
  File "F:\python3.6.5\lib\site-packages\django\db\models\query.py", line 1179, in _fetch_all
    self._result_cache = list(self._iterable_class(self))
  File "F:\python3.6.5\lib\site-packages\django\db\models\query.py", line 53, in __iter__
    results = compiler.execute_sql(chunked_fetch=self.chunked_fetch, chunk_size=self.chunk_size)
  File "F:\python3.6.5\lib\site-packages\django\db\models\sql\compiler.py", line 1068, in execute_sql
    cursor.execute(sql, params)
  File "F:\python3.6.5\lib\site-packages\django\db\backends\utils.py", line 100, in execute
    return super().execute(sql, params)
  File "F:\python3.6.5\lib\site-packages\django\db\backends\utils.py", line 68, in execute
    return self._execute_with_wrappers(sql, params, many=False, executor=self._execute)
  File "F:\python3.6.5\lib\site-packages\django\db\backends\utils.py", line 77, in _execute_with_wrappers
    return executor(sql, params, many, context)
  File "F:\python3.6.5\lib\site-packages\django\db\backends\utils.py", line 85, in _execute
    return self.cursor.execute(sql, params)
  File "F:\python3.6.5\lib\site-packages\django\db\utils.py", line 89, in __exit__
    raise dj_exc_value.with_traceback(traceback) from exc_value
  File "F:\python3.6.5\lib\site-packages\django\db\backends\utils.py", line 85, in _execute
    return self.cursor.execute(sql, params)
  File "F:\python3.6.5\lib\site-packages\django\db\backends\sqlite3\base.py", line 303, in execute
    return Database.Cursor.execute(self, query, params)
django.db.utils.OperationalError: no such table: django_session
2018-11-22 00:38:35,416 - ERROR----  Internal Server Error: /add/case/
Traceback (most recent call last):
  File "F:\python3.6.5\lib\site-packages\django\contrib\sessions\backends\base.py", line 191, in _get_session
    return self._session_cache
AttributeError: 'SessionStore' object has no attribute '_session_cache'

During handling of the above exception, another exception occurred:

Traceback (most recent call last):
  File "F:\python3.6.5\lib\site-packages\django\db\backends\utils.py", line 85, in _execute
    return self.cursor.execute(sql, params)
  File "F:\python3.6.5\lib\site-packages\django\db\backends\sqlite3\base.py", line 303, in execute
    return Database.Cursor.execute(self, query, params)
sqlite3.OperationalError: no such table: django_session

The above exception was the direct cause of the following exception:

Traceback (most recent call last):
  File "F:\python3.6.5\lib\site-packages\django\core\handlers\exception.py", line 35, in inner
    response = get_response(request)
  File "F:\python3.6.5\lib\site-packages\django\core\handlers\base.py", line 128, in _get_response
    response = self.process_exception_by_middleware(e, request)
  File "F:\python3.6.5\lib\site-packages\django\core\handlers\base.py", line 126, in _get_response
    response = wrapped_callback(request, *callback_args, **callback_kwargs)
  File "F:/pythonProject/AutoDot\DotDotDot\views.py", line 159, in add_case_page
    request.session['msg'] = context
  File "F:\python3.6.5\lib\site-packages\django\contrib\sessions\backends\base.py", line 58, in __setitem__
    self._session[key] = value
  File "F:\python3.6.5\lib\site-packages\django\contrib\sessions\backends\base.py", line 196, in _get_session
    self._session_cache = self.load()
  File "F:\python3.6.5\lib\site-packages\django\contrib\sessions\backends\db.py", line 34, in load
    expire_date__gt=timezone.now()
  File "F:\python3.6.5\lib\site-packages\django\db\models\manager.py", line 82, in manager_method
    return getattr(self.get_queryset(), name)(*args, **kwargs)
  File "F:\python3.6.5\lib\site-packages\django\db\models\query.py", line 397, in get
    num = len(clone)
  File "F:\python3.6.5\lib\site-packages\django\db\models\query.py", line 254, in __len__
    self._fetch_all()
  File "F:\python3.6.5\lib\site-packages\django\db\models\query.py", line 1179, in _fetch_all
    self._result_cache = list(self._iterable_class(self))
  File "F:\python3.6.5\lib\site-packages\django\db\models\query.py", line 53, in __iter__
    results = compiler.execute_sql(chunked_fetch=self.chunked_fetch, chunk_size=self.chunk_size)
  File "F:\python3.6.5\lib\site-packages\django\db\models\sql\compiler.py", line 1068, in execute_sql
    cursor.execute(sql, params)
  File "F:\python3.6.5\lib\site-packages\django\db\backends\utils.py", line 100, in execute
    return super().execute(sql, params)
  File "F:\python3.6.5\lib\site-packages\django\db\backends\utils.py", line 68, in execute
    return self._execute_with_wrappers(sql, params, many=False, executor=self._execute)
  File "F:\python3.6.5\lib\site-packages\django\db\backends\utils.py", line 77, in _execute_with_wrappers
    return executor(sql, params, many, context)
  File "F:\python3.6.5\lib\site-packages\django\db\backends\utils.py", line 85, in _execute
    return self.cursor.execute(sql, params)
  File "F:\python3.6.5\lib\site-packages\django\db\utils.py", line 89, in __exit__
    raise dj_exc_value.with_traceback(traceback) from exc_value
  File "F:\python3.6.5\lib\site-packages\django\db\backends\utils.py", line 85, in _execute
    return self.cursor.execute(sql, params)
  File "F:\python3.6.5\lib\site-packages\django\db\backends\sqlite3\base.py", line 303, in execute
    return Database.Cursor.execute(self, query, params)
django.db.utils.OperationalError: no such table: django_session
2018-11-22 00:38:36,333 - ERROR----  Internal Server Error: /add/case/
Traceback (most recent call last):
  File "F:\python3.6.5\lib\site-packages\django\contrib\sessions\backends\base.py", line 191, in _get_session
    return self._session_cache
AttributeError: 'SessionStore' object has no attribute '_session_cache'

During handling of the above exception, another exception occurred:

Traceback (most recent call last):
  File "F:\python3.6.5\lib\site-packages\django\db\backends\utils.py", line 85, in _execute
    return self.cursor.execute(sql, params)
  File "F:\python3.6.5\lib\site-packages\django\db\backends\sqlite3\base.py", line 303, in execute
    return Database.Cursor.execute(self, query, params)
sqlite3.OperationalError: no such table: django_session

The above exception was the direct cause of the following exception:

Traceback (most recent call last):
  File "F:\python3.6.5\lib\site-packages\django\core\handlers\exception.py", line 35, in inner
    response = get_response(request)
  File "F:\python3.6.5\lib\site-packages\django\core\handlers\base.py", line 128, in _get_response
    response = self.process_exception_by_middleware(e, request)
  File "F:\python3.6.5\lib\site-packages\django\core\handlers\base.py", line 126, in _get_response
    response = wrapped_callback(request, *callback_args, **callback_kwargs)
  File "F:/pythonProject/AutoDot\DotDotDot\views.py", line 159, in add_case_page
    request.session['msg'] = context
  File "F:\python3.6.5\lib\site-packages\django\contrib\sessions\backends\base.py", line 58, in __setitem__
    self._session[key] = value
  File "F:\python3.6.5\lib\site-packages\django\contrib\sessions\backends\base.py", line 196, in _get_session
    self._session_cache = self.load()
  File "F:\python3.6.5\lib\site-packages\django\contrib\sessions\backends\db.py", line 34, in load
    expire_date__gt=timezone.now()
  File "F:\python3.6.5\lib\site-packages\django\db\models\manager.py", line 82, in manager_method
    return getattr(self.get_queryset(), name)(*args, **kwargs)
  File "F:\python3.6.5\lib\site-packages\django\db\models\query.py", line 397, in get
    num = len(clone)
  File "F:\python3.6.5\lib\site-packages\django\db\models\query.py", line 254, in __len__
    self._fetch_all()
  File "F:\python3.6.5\lib\site-packages\django\db\models\query.py", line 1179, in _fetch_all
    self._result_cache = list(self._iterable_class(self))
  File "F:\python3.6.5\lib\site-packages\django\db\models\query.py", line 53, in __iter__
    results = compiler.execute_sql(chunked_fetch=self.chunked_fetch, chunk_size=self.chunk_size)
  File "F:\python3.6.5\lib\site-packages\django\db\models\sql\compiler.py", line 1068, in execute_sql
    cursor.execute(sql, params)
  File "F:\python3.6.5\lib\site-packages\django\db\backends\utils.py", line 100, in execute
    return super().execute(sql, params)
  File "F:\python3.6.5\lib\site-packages\django\db\backends\utils.py", line 68, in execute
    return self._execute_with_wrappers(sql, params, many=False, executor=self._execute)
  File "F:\python3.6.5\lib\site-packages\django\db\backends\utils.py", line 77, in _execute_with_wrappers
    return executor(sql, params, many, context)
  File "F:\python3.6.5\lib\site-packages\django\db\backends\utils.py", line 85, in _execute
    return self.cursor.execute(sql, params)
  File "F:\python3.6.5\lib\site-packages\django\db\utils.py", line 89, in __exit__
    raise dj_exc_value.with_traceback(traceback) from exc_value
  File "F:\python3.6.5\lib\site-packages\django\db\backends\utils.py", line 85, in _execute
    return self.cursor.execute(sql, params)
  File "F:\python3.6.5\lib\site-packages\django\db\backends\sqlite3\base.py", line 303, in execute
    return Database.Cursor.execute(self, query, params)
django.db.utils.OperationalError: no such table: django_session
2018-11-22 00:38:36,918 - ERROR----  Internal Server Error: /add/case/
Traceback (most recent call last):
  File "F:\python3.6.5\lib\site-packages\django\contrib\sessions\backends\base.py", line 191, in _get_session
    return self._session_cache
AttributeError: 'SessionStore' object has no attribute '_session_cache'

During handling of the above exception, another exception occurred:

Traceback (most recent call last):
  File "F:\python3.6.5\lib\site-packages\django\db\backends\utils.py", line 85, in _execute
    return self.cursor.execute(sql, params)
  File "F:\python3.6.5\lib\site-packages\django\db\backends\sqlite3\base.py", line 303, in execute
    return Database.Cursor.execute(self, query, params)
sqlite3.OperationalError: no such table: django_session

The above exception was the direct cause of the following exception:

Traceback (most recent call last):
  File "F:\python3.6.5\lib\site-packages\django\core\handlers\exception.py", line 35, in inner
    response = get_response(request)
  File "F:\python3.6.5\lib\site-packages\django\core\handlers\base.py", line 128, in _get_response
    response = self.process_exception_by_middleware(e, request)
  File "F:\python3.6.5\lib\site-packages\django\core\handlers\base.py", line 126, in _get_response
    response = wrapped_callback(request, *callback_args, **callback_kwargs)
  File "F:/pythonProject/AutoDot\DotDotDot\views.py", line 159, in add_case_page
    request.session['msg'] = context
  File "F:\python3.6.5\lib\site-packages\django\contrib\sessions\backends\base.py", line 58, in __setitem__
    self._session[key] = value
  File "F:\python3.6.5\lib\site-packages\django\contrib\sessions\backends\base.py", line 196, in _get_session
    self._session_cache = self.load()
  File "F:\python3.6.5\lib\site-packages\django\contrib\sessions\backends\db.py", line 34, in load
    expire_date__gt=timezone.now()
  File "F:\python3.6.5\lib\site-packages\django\db\models\manager.py", line 82, in manager_method
    return getattr(self.get_queryset(), name)(*args, **kwargs)
  File "F:\python3.6.5\lib\site-packages\django\db\models\query.py", line 397, in get
    num = len(clone)
  File "F:\python3.6.5\lib\site-packages\django\db\models\query.py", line 254, in __len__
    self._fetch_all()
  File "F:\python3.6.5\lib\site-packages\django\db\models\query.py", line 1179, in _fetch_all
    self._result_cache = list(self._iterable_class(self))
  File "F:\python3.6.5\lib\site-packages\django\db\models\query.py", line 53, in __iter__
    results = compiler.execute_sql(chunked_fetch=self.chunked_fetch, chunk_size=self.chunk_size)
  File "F:\python3.6.5\lib\site-packages\django\db\models\sql\compiler.py", line 1068, in execute_sql
    cursor.execute(sql, params)
  File "F:\python3.6.5\lib\site-packages\django\db\backends\utils.py", line 100, in execute
    return super().execute(sql, params)
  File "F:\python3.6.5\lib\site-packages\django\db\backends\utils.py", line 68, in execute
    return self._execute_with_wrappers(sql, params, many=False, executor=self._execute)
  File "F:\python3.6.5\lib\site-packages\django\db\backends\utils.py", line 77, in _execute_with_wrappers
    return executor(sql, params, many, context)
  File "F:\python3.6.5\lib\site-packages\django\db\backends\utils.py", line 85, in _execute
    return self.cursor.execute(sql, params)
  File "F:\python3.6.5\lib\site-packages\django\db\utils.py", line 89, in __exit__
    raise dj_exc_value.with_traceback(traceback) from exc_value
  File "F:\python3.6.5\lib\site-packages\django\db\backends\utils.py", line 85, in _execute
    return self.cursor.execute(sql, params)
  File "F:\python3.6.5\lib\site-packages\django\db\backends\sqlite3\base.py", line 303, in execute
    return Database.Cursor.execute(self, query, params)
django.db.utils.OperationalError: no such table: django_session
2018-11-22 00:38:37,159 - ERROR----  Internal Server Error: /add/case/
Traceback (most recent call last):
  File "F:\python3.6.5\lib\site-packages\django\contrib\sessions\backends\base.py", line 191, in _get_session
    return self._session_cache
AttributeError: 'SessionStore' object has no attribute '_session_cache'

During handling of the above exception, another exception occurred:

Traceback (most recent call last):
  File "F:\python3.6.5\lib\site-packages\django\db\backends\utils.py", line 85, in _execute
    return self.cursor.execute(sql, params)
  File "F:\python3.6.5\lib\site-packages\django\db\backends\sqlite3\base.py", line 303, in execute
    return Database.Cursor.execute(self, query, params)
sqlite3.OperationalError: no such table: django_session

The above exception was the direct cause of the following exception:

Traceback (most recent call last):
  File "F:\python3.6.5\lib\site-packages\django\core\handlers\exception.py", line 35, in inner
    response = get_response(request)
  File "F:\python3.6.5\lib\site-packages\django\core\handlers\base.py", line 128, in _get_response
    response = self.process_exception_by_middleware(e, request)
  File "F:\python3.6.5\lib\site-packages\django\core\handlers\base.py", line 126, in _get_response
    response = wrapped_callback(request, *callback_args, **callback_kwargs)
  File "F:/pythonProject/AutoDot\DotDotDot\views.py", line 159, in add_case_page
    request.session['msg'] = context
  File "F:\python3.6.5\lib\site-packages\django\contrib\sessions\backends\base.py", line 58, in __setitem__
    self._session[key] = value
  File "F:\python3.6.5\lib\site-packages\django\contrib\sessions\backends\base.py", line 196, in _get_session
    self._session_cache = self.load()
  File "F:\python3.6.5\lib\site-packages\django\contrib\sessions\backends\db.py", line 34, in load
    expire_date__gt=timezone.now()
  File "F:\python3.6.5\lib\site-packages\django\db\models\manager.py", line 82, in manager_method
    return getattr(self.get_queryset(), name)(*args, **kwargs)
  File "F:\python3.6.5\lib\site-packages\django\db\models\query.py", line 397, in get
    num = len(clone)
  File "F:\python3.6.5\lib\site-packages\django\db\models\query.py", line 254, in __len__
    self._fetch_all()
  File "F:\python3.6.5\lib\site-packages\django\db\models\query.py", line 1179, in _fetch_all
    self._result_cache = list(self._iterable_class(self))
  File "F:\python3.6.5\lib\site-packages\django\db\models\query.py", line 53, in __iter__
    results = compiler.execute_sql(chunked_fetch=self.chunked_fetch, chunk_size=self.chunk_size)
  File "F:\python3.6.5\lib\site-packages\django\db\models\sql\compiler.py", line 1068, in execute_sql
    cursor.execute(sql, params)
  File "F:\python3.6.5\lib\site-packages\django\db\backends\utils.py", line 100, in execute
    return super().execute(sql, params)
  File "F:\python3.6.5\lib\site-packages\django\db\backends\utils.py", line 68, in execute
    return self._execute_with_wrappers(sql, params, many=False, executor=self._execute)
  File "F:\python3.6.5\lib\site-packages\django\db\backends\utils.py", line 77, in _execute_with_wrappers
    return executor(sql, params, many, context)
  File "F:\python3.6.5\lib\site-packages\django\db\backends\utils.py", line 85, in _execute
    return self.cursor.execute(sql, params)
  File "F:\python3.6.5\lib\site-packages\django\db\utils.py", line 89, in __exit__
    raise dj_exc_value.with_traceback(traceback) from exc_value
  File "F:\python3.6.5\lib\site-packages\django\db\backends\utils.py", line 85, in _execute
    return self.cursor.execute(sql, params)
  File "F:\python3.6.5\lib\site-packages\django\db\backends\sqlite3\base.py", line 303, in execute
    return Database.Cursor.execute(self, query, params)
django.db.utils.OperationalError: no such table: django_session
2018-11-22 00:38:38,381 - ERROR----  Internal Server Error: /add/case/
Traceback (most recent call last):
  File "F:\python3.6.5\lib\site-packages\django\contrib\sessions\backends\base.py", line 191, in _get_session
    return self._session_cache
AttributeError: 'SessionStore' object has no attribute '_session_cache'

During handling of the above exception, another exception occurred:

Traceback (most recent call last):
  File "F:\python3.6.5\lib\site-packages\django\db\backends\utils.py", line 85, in _execute
    return self.cursor.execute(sql, params)
  File "F:\python3.6.5\lib\site-packages\django\db\backends\sqlite3\base.py", line 303, in execute
    return Database.Cursor.execute(self, query, params)
sqlite3.OperationalError: no such table: django_session

The above exception was the direct cause of the following exception:

Traceback (most recent call last):
  File "F:\python3.6.5\lib\site-packages\django\core\handlers\exception.py", line 35, in inner
    response = get_response(request)
  File "F:\python3.6.5\lib\site-packages\django\core\handlers\base.py", line 128, in _get_response
    response = self.process_exception_by_middleware(e, request)
  File "F:\python3.6.5\lib\site-packages\django\core\handlers\base.py", line 126, in _get_response
    response = wrapped_callback(request, *callback_args, **callback_kwargs)
  File "F:/pythonProject/AutoDot\DotDotDot\views.py", line 159, in add_case_page
    request.session['msg'] = context
  File "F:\python3.6.5\lib\site-packages\django\contrib\sessions\backends\base.py", line 58, in __setitem__
    self._session[key] = value
  File "F:\python3.6.5\lib\site-packages\django\contrib\sessions\backends\base.py", line 196, in _get_session
    self._session_cache = self.load()
  File "F:\python3.6.5\lib\site-packages\django\contrib\sessions\backends\db.py", line 34, in load
    expire_date__gt=timezone.now()
  File "F:\python3.6.5\lib\site-packages\django\db\models\manager.py", line 82, in manager_method
    return getattr(self.get_queryset(), name)(*args, **kwargs)
  File "F:\python3.6.5\lib\site-packages\django\db\models\query.py", line 397, in get
    num = len(clone)
  File "F:\python3.6.5\lib\site-packages\django\db\models\query.py", line 254, in __len__
    self._fetch_all()
  File "F:\python3.6.5\lib\site-packages\django\db\models\query.py", line 1179, in _fetch_all
    self._result_cache = list(self._iterable_class(self))
  File "F:\python3.6.5\lib\site-packages\django\db\models\query.py", line 53, in __iter__
    results = compiler.execute_sql(chunked_fetch=self.chunked_fetch, chunk_size=self.chunk_size)
  File "F:\python3.6.5\lib\site-packages\django\db\models\sql\compiler.py", line 1068, in execute_sql
    cursor.execute(sql, params)
  File "F:\python3.6.5\lib\site-packages\django\db\backends\utils.py", line 100, in execute
    return super().execute(sql, params)
  File "F:\python3.6.5\lib\site-packages\django\db\backends\utils.py", line 68, in execute
    return self._execute_with_wrappers(sql, params, many=False, executor=self._execute)
  File "F:\python3.6.5\lib\site-packages\django\db\backends\utils.py", line 77, in _execute_with_wrappers
    return executor(sql, params, many, context)
  File "F:\python3.6.5\lib\site-packages\django\db\backends\utils.py", line 85, in _execute
    return self.cursor.execute(sql, params)
  File "F:\python3.6.5\lib\site-packages\django\db\utils.py", line 89, in __exit__
    raise dj_exc_value.with_traceback(traceback) from exc_value
  File "F:\python3.6.5\lib\site-packages\django\db\backends\utils.py", line 85, in _execute
    return self.cursor.execute(sql, params)
  File "F:\python3.6.5\lib\site-packages\django\db\backends\sqlite3\base.py", line 303, in execute
    return Database.Cursor.execute(self, query, params)
django.db.utils.OperationalError: no such table: django_session
2018-11-22 00:38:52,638 - ERROR----  Internal Server Error: /add/case/
Traceback (most recent call last):
  File "F:\python3.6.5\lib\site-packages\django\contrib\sessions\backends\base.py", line 191, in _get_session
    return self._session_cache
AttributeError: 'SessionStore' object has no attribute '_session_cache'

During handling of the above exception, another exception occurred:

Traceback (most recent call last):
  File "F:\python3.6.5\lib\site-packages\django\db\backends\utils.py", line 85, in _execute
    return self.cursor.execute(sql, params)
  File "F:\python3.6.5\lib\site-packages\django\db\backends\sqlite3\base.py", line 303, in execute
    return Database.Cursor.execute(self, query, params)
sqlite3.OperationalError: no such table: django_session

The above exception was the direct cause of the following exception:

Traceback (most recent call last):
  File "F:\python3.6.5\lib\site-packages\django\core\handlers\exception.py", line 35, in inner
    response = get_response(request)
  File "F:\python3.6.5\lib\site-packages\django\core\handlers\base.py", line 128, in _get_response
    response = self.process_exception_by_middleware(e, request)
  File "F:\python3.6.5\lib\site-packages\django\core\handlers\base.py", line 126, in _get_response
    response = wrapped_callback(request, *callback_args, **callback_kwargs)
  File "F:/pythonProject/AutoDot\DotDotDot\views.py", line 159, in add_case_page
    request.session['msg'] = context
  File "F:\python3.6.5\lib\site-packages\django\contrib\sessions\backends\base.py", line 58, in __setitem__
    self._session[key] = value
  File "F:\python3.6.5\lib\site-packages\django\contrib\sessions\backends\base.py", line 196, in _get_session
    self._session_cache = self.load()
  File "F:\python3.6.5\lib\site-packages\django\contrib\sessions\backends\db.py", line 34, in load
    expire_date__gt=timezone.now()
  File "F:\python3.6.5\lib\site-packages\django\db\models\manager.py", line 82, in manager_method
    return getattr(self.get_queryset(), name)(*args, **kwargs)
  File "F:\python3.6.5\lib\site-packages\django\db\models\query.py", line 397, in get
    num = len(clone)
  File "F:\python3.6.5\lib\site-packages\django\db\models\query.py", line 254, in __len__
    self._fetch_all()
  File "F:\python3.6.5\lib\site-packages\django\db\models\query.py", line 1179, in _fetch_all
    self._result_cache = list(self._iterable_class(self))
  File "F:\python3.6.5\lib\site-packages\django\db\models\query.py", line 53, in __iter__
    results = compiler.execute_sql(chunked_fetch=self.chunked_fetch, chunk_size=self.chunk_size)
  File "F:\python3.6.5\lib\site-packages\django\db\models\sql\compiler.py", line 1068, in execute_sql
    cursor.execute(sql, params)
  File "F:\python3.6.5\lib\site-packages\django\db\backends\utils.py", line 100, in execute
    return super().execute(sql, params)
  File "F:\python3.6.5\lib\site-packages\django\db\backends\utils.py", line 68, in execute
    return self._execute_with_wrappers(sql, params, many=False, executor=self._execute)
  File "F:\python3.6.5\lib\site-packages\django\db\backends\utils.py", line 77, in _execute_with_wrappers
    return executor(sql, params, many, context)
  File "F:\python3.6.5\lib\site-packages\django\db\backends\utils.py", line 85, in _execute
    return self.cursor.execute(sql, params)
  File "F:\python3.6.5\lib\site-packages\django\db\utils.py", line 89, in __exit__
    raise dj_exc_value.with_traceback(traceback) from exc_value
  File "F:\python3.6.5\lib\site-packages\django\db\backends\utils.py", line 85, in _execute
    return self.cursor.execute(sql, params)
  File "F:\python3.6.5\lib\site-packages\django\db\backends\sqlite3\base.py", line 303, in execute
    return Database.Cursor.execute(self, query, params)
django.db.utils.OperationalError: no such table: django_session
2018-11-22 00:39:39,855 - ERROR----  Internal Server Error: /add/case/
Traceback (most recent call last):
  File "F:\python3.6.5\lib\site-packages\django\contrib\sessions\backends\base.py", line 191, in _get_session
    return self._session_cache
AttributeError: 'SessionStore' object has no attribute '_session_cache'

During handling of the above exception, another exception occurred:

Traceback (most recent call last):
  File "F:\python3.6.5\lib\site-packages\django\db\backends\utils.py", line 85, in _execute
    return self.cursor.execute(sql, params)
  File "F:\python3.6.5\lib\site-packages\django\db\backends\sqlite3\base.py", line 303, in execute
    return Database.Cursor.execute(self, query, params)
sqlite3.OperationalError: no such table: django_session

The above exception was the direct cause of the following exception:

Traceback (most recent call last):
  File "F:\python3.6.5\lib\site-packages\django\core\handlers\exception.py", line 35, in inner
    response = get_response(request)
  File "F:\python3.6.5\lib\site-packages\django\core\handlers\base.py", line 128, in _get_response
    response = self.process_exception_by_middleware(e, request)
  File "F:\python3.6.5\lib\site-packages\django\core\handlers\base.py", line 126, in _get_response
    response = wrapped_callback(request, *callback_args, **callback_kwargs)
  File "F:/pythonProject/AutoDot\DotDotDot\views.py", line 159, in add_case_page
    request.session['msg'] = context
  File "F:\python3.6.5\lib\site-packages\django\contrib\sessions\backends\base.py", line 58, in __setitem__
    self._session[key] = value
  File "F:\python3.6.5\lib\site-packages\django\contrib\sessions\backends\base.py", line 196, in _get_session
    self._session_cache = self.load()
  File "F:\python3.6.5\lib\site-packages\django\contrib\sessions\backends\db.py", line 34, in load
    expire_date__gt=timezone.now()
  File "F:\python3.6.5\lib\site-packages\django\db\models\manager.py", line 82, in manager_method
    return getattr(self.get_queryset(), name)(*args, **kwargs)
  File "F:\python3.6.5\lib\site-packages\django\db\models\query.py", line 397, in get
    num = len(clone)
  File "F:\python3.6.5\lib\site-packages\django\db\models\query.py", line 254, in __len__
    self._fetch_all()
  File "F:\python3.6.5\lib\site-packages\django\db\models\query.py", line 1179, in _fetch_all
    self._result_cache = list(self._iterable_class(self))
  File "F:\python3.6.5\lib\site-packages\django\db\models\query.py", line 53, in __iter__
    results = compiler.execute_sql(chunked_fetch=self.chunked_fetch, chunk_size=self.chunk_size)
  File "F:\python3.6.5\lib\site-packages\django\db\models\sql\compiler.py", line 1068, in execute_sql
    cursor.execute(sql, params)
  File "F:\python3.6.5\lib\site-packages\django\db\backends\utils.py", line 100, in execute
    return super().execute(sql, params)
  File "F:\python3.6.5\lib\site-packages\django\db\backends\utils.py", line 68, in execute
    return self._execute_with_wrappers(sql, params, many=False, executor=self._execute)
  File "F:\python3.6.5\lib\site-packages\django\db\backends\utils.py", line 77, in _execute_with_wrappers
    return executor(sql, params, many, context)
  File "F:\python3.6.5\lib\site-packages\django\db\backends\utils.py", line 85, in _execute
    return self.cursor.execute(sql, params)
  File "F:\python3.6.5\lib\site-packages\django\db\utils.py", line 89, in __exit__
    raise dj_exc_value.with_traceback(traceback) from exc_value
  File "F:\python3.6.5\lib\site-packages\django\db\backends\utils.py", line 85, in _execute
    return self.cursor.execute(sql, params)
  File "F:\python3.6.5\lib\site-packages\django\db\backends\sqlite3\base.py", line 303, in execute
    return Database.Cursor.execute(self, query, params)
django.db.utils.OperationalError: no such table: django_session
2018-11-22 00:41:51,309 - INFO----  当前运行文件：F:/pythonProject/AutoDot\common\DataReplace.py
2018-11-22 00:41:51,311 - INFO----  当前运行文件：F:/pythonProject/AutoDot\common\SaveDynamicData.py
2018-11-22 00:41:51,311 - INFO----  当前运行文件：F:/pythonProject/AutoDot\common\ConfigFile.py
2018-11-22 00:41:51,445 - INFO----  ------------------------------------------------------------------
2018-11-22 00:41:51,445 - INFO----  当前运行文件：F:/pythonProject/AutoDot\common\HttpRequest.py
2018-11-22 00:41:53,100 - INFO----  Expand macros in F:\python3.6.5\lib\site-packages\macropy\core\hquotes.py
2018-11-22 00:41:53,100 - INFO----  Finding macros in 'macropy.core.hquotes'
2018-11-22 00:41:53,100 - INFO----  Importing macros from 'macropy.core.quotes' into 'macropy.core.hquotes'
2018-11-22 00:41:53,100 - INFO----  Expand macros in F:\python3.6.5\lib\site-packages\macropy\core\quotes.py
2018-11-22 00:41:53,100 - INFO----  Finding macros in 'macropy.core.quotes'
2018-11-22 00:41:53,131 - DEBUG----  Found macro 'q', type 'Block', line 48
2018-11-22 00:41:53,146 - DEBUG----  Found macro 'q', type 'Block', line 58
2018-11-22 00:41:53,178 - INFO----  Expand macros in F:\python3.6.5\lib\site-packages\macropy\core\failure.py
2018-11-22 00:41:53,178 - INFO----  Finding macros in 'macropy.core.failure'
2018-11-22 00:41:53,178 - INFO----  Importing macros from 'macropy.core.hquotes' into 'macropy.core.failure'
2018-11-22 00:41:53,178 - DEBUG----  Found macro 'hq', type 'Expr', line 29
2018-11-22 00:41:53,200 - DEBUG----  declare 'pyecharts_js_extension' plugin manager
2018-11-22 00:41:53,200 - DEBUG----  scanning for plugins...
2018-11-22 00:41:53,316 - DEBUG----  register Pypkg
2018-11-22 00:41:53,331 - DEBUG----  found jupyter_echarts_pypkg
2018-11-22 00:41:53,333 - DEBUG----  Loader for pyecharts_snapshot was unable to find the sources
2018-11-22 00:41:53,335 - ERROR----  failed to import pyecharts_snapshot
Traceback (most recent call last):
  File "F:\python3.6.5\lib\site-packages\lml\utils.py", line 43, in do_import
    plugin_module = __import__(plugin_module_name)
ModuleNotFoundError: No module named 'pyecharts_snapshot'
2018-11-22 00:41:53,335 - DEBUG----  pyecharts_snapshot
2018-11-22 00:41:53,336 - DEBUG----  No module named 'pyecharts_snapshot'
2018-11-22 00:41:53,336 - DEBUG----  scanning done
2018-11-22 00:41:53,344 - DEBUG----  caching EchartsEnvironment
2018-11-22 00:41:53,344 - DEBUG----  declare 'pyecharts_environment' plugin manager
2018-11-22 00:41:53,344 - DEBUG----  load cached plugin info: EchartsEnvironment
2018-11-22 00:41:53,345 - DEBUG----  load None later
2018-11-22 00:41:53,364 - DEBUG----  caching DefaultChinaDataBank
2018-11-22 00:41:53,364 - DEBUG----  declare 'pyecharts_geo_data_bank' plugin manager
2018-11-22 00:41:53,364 - DEBUG----  load cached plugin info: DefaultChinaDataBank
2018-11-22 00:41:53,364 - DEBUG----  load None later
2018-11-22 00:41:53,432 - DEBUG----  Loader for django.contrib.auth.templatetags was unable to find the sources
2018-11-22 00:41:53,432 - DEBUG----  Loader for django.contrib.contenttypes.templatetags was unable to find the sources
2018-11-22 00:41:53,432 - DEBUG----  Loader for django.contrib.sessions.templatetags was unable to find the sources
2018-11-22 00:41:53,432 - DEBUG----  Loader for django.contrib.messages.templatetags was unable to find the sources
2018-11-22 00:41:53,432 - DEBUG----  Loader for DotDotDot.templatetags was unable to find the sources
2018-11-22 00:41:53,479 - DEBUG----  Loader for django.contrib.messages.migrations was unable to find the sources
2018-11-22 00:41:53,479 - DEBUG----  Loader for django.contrib.staticfiles.migrations was unable to find the sources
2018-11-22 00:41:58,052 - INFO----  ------------------------------------------------------------------
2018-11-22 00:41:58,052 - INFO----  当前运行文件：F:/pythonProject/AutoDot\common\GetProjectName.py
2018-11-22 00:41:58,053 - INFO----  F:\pythonProject\AutoDot\case文件下的用例文件 ['自动干线.xlsx']
2018-11-22 00:41:58,112 - INFO----  ------------------------------------------------------------------
2018-11-22 00:41:58,112 - INFO----  当前运行文件：F:/pythonProject/AutoDot\common\GetProjectName.py
2018-11-22 00:41:58,113 - INFO----  F:\pythonProject\AutoDot\case文件下的用例文件 ['自动干线.xlsx']
2018-11-22 00:42:01,035 - INFO----  ------------------------------------------------------------------
2018-11-22 00:42:01,036 - INFO----  当前运行文件：F:/pythonProject/AutoDot\common\GetProjectCase.py
2018-11-22 00:42:01,036 - INFO----  准备获取 自动干线 项目的用例路径
2018-11-22 00:42:01,036 - INFO----  获取到 自动干线 项目的用例路径：F:\pythonProject\AutoDot\case\自动干线.xlsx
2018-11-22 00:42:01,048 - INFO----  获取用例的标题：['ID', 'Run', 'Sort', 'Sql', 'ModuleName', 'CaseName', 'CaseDescription', 'Protocol', 'Host', 'Method', 'Headers', 'Path', 'Data', 'Files', 'ReplaceID', 'Expect', 'CheckPoint', 'Response', 'TransmitID', 'TransmitTargetID', 'Remark', 'CreateDate', 'UpdateTime', 'Author', 'Editor', 'RunResult']
2018-11-22 00:42:02,342 - INFO----  读取配置文件F:\pythonProject\AutoDot\config\自动干线.ini
2018-11-22 00:42:02,343 - INFO----  获取配置文件所有sections：['reportName', 'changeData']
2018-11-22 00:42:02,343 - INFO----  获取配置文件sections：changeData 下的options：{}
2018-11-22 00:42:17,173 - INFO----  ------------------------------------------------------------------
2018-11-22 00:42:17,173 - INFO----  当前运行文件：F:/pythonProject/AutoDot\common\GetProjectCase.py
2018-11-22 00:42:17,173 - INFO----  准备获取 自动干线 项目的用例路径
2018-11-22 00:42:17,173 - INFO----  获取到 自动干线 项目的用例路径：F:\pythonProject\AutoDot\case\自动干线.xlsx
2018-11-22 00:42:17,180 - INFO----  获取用例的标题：['ID', 'Run', 'Sort', 'Sql', 'ModuleName', 'CaseName', 'CaseDescription', 'Protocol', 'Host', 'Method', 'Headers', 'Path', 'Data', 'Files', 'ReplaceID', 'Expect', 'CheckPoint', 'Response', 'TransmitID', 'TransmitTargetID', 'Remark', 'CreateDate', 'UpdateTime', 'Author', 'Editor', 'RunResult']
2018-11-22 00:42:19,561 - INFO----  读取配置文件F:\pythonProject\AutoDot\config\自动干线.ini
2018-11-22 00:42:19,562 - INFO----  获取配置文件所有sections：['reportName', 'changeData']
2018-11-22 00:42:19,562 - INFO----  获取配置文件sections：changeData 下的options：{}
